Workbook

Sheet Anleitung
A1: Urlaubsplaner Kreativtherapie-Team
A2: Gemeinsame Übersicht der Urlaubswünsche. Das ist KEIN Genehmigungsverfahren: Die Datei zeigt, wann es im eigenen Fachteam oder auf einer Station eng wird, damit man sich rechtzeitig abspricht.
A4: SO TRAGE ICH MEINEN URLAUB EIN
A5: 1. Blatt »Urlaub« öffnen, nächste freie Zeile suchen.
A6: 2. Spalte A: eigenen Namen aus der Liste wählen (nicht tippen – die Liste kommt aus dem Blatt »Team«).
A7: 3. Von / Bis als Datum eintragen (z. B. 12.07.2027). Ein einzelner Tag: Von = Bis.
A8: 4. Status wählen: Wunsch = noch offen · abgesprochen = mit Kolleg:innen geklärt · eingereicht = offiziell beantragt.
A9: 5. Spalten F–J füllen sich selbst. Steht in »Hinweis« ›Engpass – bitte absprechen‹, sind im Zeitraum an mindestens einem Tag mehr Personen weg als erlaubt (Spalte H = im Fachteam, Spalte I = auf einer meiner Stationen).
A10: 6. Bei Engpass: im Blatt »Kalender« nachsehen, wer betroffen ist (rote Felder), und sich absprechen. Danach Zeitraum anpassen oder in »Bemerkung« die Absprache notieren.
A11: 7. Urlaub verschoben? Einfach Von/Bis in der eigenen Zeile ändern. Urlaub fällt weg? Zeile leeren (Inhalte löschen).
A12: 8. Datei speichern und schließen (siehe »Ablage« unten).
A14: SO LESE ICH DEN KALENDER
... A39: Blatt »Konflikt« ist ein ausgeblendetes Hilfsblatt (Rechnung, welche Tage über der Grenze liegen). Nicht bearbeiten.

Sheet Einstellungen
A1: Einstellungen
A3: Startdatum Planungszeitraum | B3: 46388 | C3: ← eintragen. Der Kalender zeigt ab hier 366 Tage.
A4: Letzter Tag (berechnet) | B4: =B3+365 -> 46753
I5: Bundesweite Feiertage vorbelegt – Landesfeiertage ergänzen!
A6: Fachrichtung | B6: Max. gleichzeitig im Urlaub | C6: Personen im Team | E6: Station | F6: Max. gleichzeitig im Urlaub | G6: Therapeut:innen auf Station | I6: Feiertag / Schließtag | J6: Bezeichnung
A7: Ergotherapie | B7: 3 | C7: =IF(A7="","",COUNTIF(Team!$B$5:$B$64,A7)) -> 3 | E7: Station 1A | F7: 2 | G7: =IF(E7="","",COUNTIF(Team!$C$5:$F$64,E7)) -> 3 | I7: 46388 | J7: Neujahr
A8: Musiktherapie | B8: 2 | C8: =IF(A8="","",COUNTIF(Team!$B$5:$B$64,A8)) -> 2 | E8: Station 1B | F8: 1 | G8: =IF(E8="","",COUNTIF(Team!$C$5:$F$64,E8)) -> 3 | I8: 46472 | J8: Karfreitag
A9: Bewegungstherapie | B9: 2 | C9: =IF(A9="","",COUNTIF(Team!$B$5:$B$64,A9)) -> 2 | E9: Station 2A | F9: 2 | G9: =IF(E9="","",COUNTIF(Team!$C$5:$F$64,E9)) -> 3 | I9: 46475 | J9: Ostermontag
A10: Kunsttherapie | B10: 1 | C10: =IF(A10="","",COUNTIF(Team!$B$5:$B$64,A10)) -> 0 | E10: Station 3 | F10: 1 | G10: =IF(E10="","",COUNTIF(Team!$C$5:$F$64,E10)) -> 3 | I10: 46508 | J10: Tag der Arbeit
C11: =IF(A11="","",COUNTIF(Team!$B$5:$B$64,A11)) | E11: Tagesklinik | F11: 1 | G11: =IF(E11="","",COUNTIF(Team!$C$5:$F$64,E11)) -> 2 | I11: 46513 | J11: Christi Himmelfahrt
C12: =IF(A12="","",COUNTIF(Team!$B$5:$B$64,A12)) | G12: =IF(E12="","",COUNTIF(Team!$C$5:$F$64,E12)) | I12: 46524 | J12: Pfingstmontag
C13: =IF(A13="","",COUNTIF(Team!$B$5:$B$64,A13)) | G13: =IF(E13="","",COUNTIF(Team!$C$5:$F$64,E13)) | I13: 46663 | J13: Tag der Deutschen Einheit
C14: =IF(A14="","",COUNTIF(Team!$B$5:$B$64,A14)) | G14: =IF(E14="","",COUNTIF(Team!$C$5:$F$64,E14)) | I14: 46746 | J14: 1. Weihnachtstag
C15: =IF(A15="","",COUNTIF(Team!$B$5:$B$64,A15)) | G15: =IF(E15="","",COUNTIF(Team!$C$5:$F$64,E15)) | I15: 46747 | J15: 2. Weihnachtstag
C16: =IF(A16="","",COUNTIF(Team!$B$5:$B$64,A16)) | G16: =IF(E16="","",COUNTIF(Team!$C$5:$F$64,E16))
G17: =IF(E17="","",COUNTIF(Team!$C$5:$F$64,E17))
G18: =IF(E18="","",COUNTIF(Team!$C$5:$F$64,E18))
G19: =IF(E19="","",COUNTIF(Team!$C$5:$F$64,E19))
G20: =IF(E20="","",COUNTIF(Team!$C$5:$F$64,E20))
G21: =IF(E21="","",COUNTIF(Team!$C$5:$F$64,E21))
G22: =IF(E22="","",COUNTIF(Team!$C$5:$F$64,E22))
G23: =IF(E23="","",COUNTIF(Team!$C$5:$F$64,E23))
G24: =IF(E24="","",COUNTIF(Team!$C$5:$F$64,E24))
G25: =IF(E25="","",COUNTIF(Team!$C$5:$F$64,E25))
G26: =IF(E26="","",COUNTIF(Team!$C$5:$F$64,E26))
G27: =IF(E27="","",COUNTIF(Team!$C$5:$F$64,E27))
G28: =IF(E28="","",COUNTIF(Team!$C$5:$F$64,E28))
... G36: =IF(E36="","",COUNTIF(Team!$C$5:$F$64,E36))

Sheet Team
A1: Team – Stammdaten
A2: Eine Zeile pro Person. Name eindeutig (z. B. »Anna M.«). Fachrichtung und Stationen aus der Liste wählen; Listen pflegt man im Blatt »Einstellungen«. Am besten nach Fachrichtung sortiert eintragen.
A4: Name | B4: Fachrichtung | C4: Station 1 | D4: Station 2 | E4: Station 3 | F4: Station 4 | G4: Bemerkung (z. B. Teilzeit)
A5: Beispiel Anna | B5: Ergotherapie | C5: Station 1A | D5: Station 1B
A6: Beispiel Ben | B6: Ergotherapie | C6: Station 2A
A7: Beispiel Clara | B7: Ergotherapie | C7: Station 3 | D7: Tagesklinik
A8: Beispiel David | B8: Musiktherapie | C8: Station 1A | D8: Station 2A
A9: Beispiel Eva | B9: Musiktherapie | C9: Station 1B | D9: Station 3
A10: Beispiel Finn | B10: Bewegungstherapie | C10: Station 1A | D10: Tagesklinik
A11: Beispiel Gül | B11: Bewegungstherapie | C11: Station 1B | D11: Station 2A | E11: Station 3

Sheet Urlaub
A1: Urlaubswünsche – hier eintragen
A2: Gelbe Spalten ausfüllen (A–E). F–J rechnen automatisch. »Engpass« heißt: an mindestens einem Tag im Zeitraum sind mehr Personen weg als erlaubt – bitte im Kalender nachsehen und absprechen.
A4: Name | B4: Von | C4: Bis | D4: Status | E4: Bemerkung / Absprache | F4: Fachrichtung | G4: Arbeitstage (Mo–Fr ohne Feiertage) | H4: Tage über Grenze im Fachteam | I4: Tage über Grenze auf meinen Stationen | J4: Hinweis
A5: Beispiel Anna | B5: 46573 | C5: 46591 | D5: abgesprochen | E5: mit Ben getauscht | F5: =IF($A5="","",IFERROR(INDEX(Team!$B$5:$B$64,MATCH($A5,Team!$A$5:$A$64,0)),"?")) -> Ergotherapie | G5: =IF(OR($A5="",$B5="",$C5="",$C5<$B5),"",NETWORKDAYS($B5,$C5,Einstellungen!$I$7:$I$40)) -> 15 | H5: =IF(OR($A5="",$B5="",$C5="",$C5<$B5),"",IF(MIN($C5,Einstellungen!$B$4)<MAX($B5,Einstellungen!$B$3),0,IFERROR(SUMPRODUCT(--(MOD(OFFSET(Konflikt!$G$4,MATCH($A5,Team!$A$5:$A$64,0),MAX($B5,Einstellungen!$B$3)-Einstellungen!$B$3,1,MIN($C5,Einstellungen!$B$4)-MAX($B5,Einstellungen!$B$3)+1),2)=1)),"?"))) -> 0 | I5: =IF(OR($A5="",$B5="",$C5="",$C5<$B5),"",IF(MIN($C5,Einstellungen!$B$4)<MAX($B5,Einstellungen!$B$3),0,IFERROR(SUMPRODUCT(--(OFFSET(Konflikt!$G$4,MATCH($A5,Team!$A$5:$A$64,0),MAX($B5,Einstellungen!$B$3)-Einstellungen!$B$3,1,MIN($C5,Einstellungen!$B$4)-MAX($B5,Einstellungen!$B$3)+1)>=2)),"?"))) -> 5 | J5: =IF($A5="","",IF(OR($B5="",$C5=""),"Von und Bis eintragen",IF($C5<$B5,"Bis liegt vor Von",IF(ISNA(MATCH($A5,Team!$A$5:$A$64,0)),"Name fehlt im Blatt Team",IF(N($H5)+N($I5)>0,"Engpass – bitte absprechen",IF(OR($B5<Einstellungen!$B$3,$C5>Einstellungen!$B$4),"Teils außerhalb des Planungszeitraums","ok")))))) -> Engpass – bitte absprechen
A6: Beispiel Ben | B6: 46594 | C6: 46612 | D6: Wunsch | F6: =IF($A6="","",IFERROR(INDEX(Team!$B$5:$B$64,MATCH($A6,Team!$A$5:$A$64,0)),"?")) -> Ergotherapie | G6: =IF(OR($A6="",$B6="",$C6="",$C6<$B6),"",NETWORKDAYS($B6,$C6,Einstellungen!$I$7:$I$40)) -> 15 | H6: =IF(OR($A6="",$B6="",$C6="",$C6<$B6),"",IF(MIN($C6,Einstellungen!$B$4)<MAX($B6,Einstellungen!$B$3),0,IFERROR(SUMPRODUCT(--(MOD(OFFSET(Konflikt!$G$4,MATCH($A6,Team!$A$5:$A$64,0),MAX($B6,Einstellungen!$B$3)-Einstellungen!$B$3,1,MIN($C6,Einstellungen!$B$4)-MAX($B6,Einstellungen!$B$3)+1),2)=1)),"?"))) -> 0 | I6: =IF(OR($A6="",$B6="",$C6="",$C6<$B6),"",IF(MIN($C6,Einstellungen!$B$4)<MAX($B6,Einstellungen!$B$3),0,IFERROR(SUMPRODUCT(--(OFFSET(Konflikt!$G$4,MATCH($A6,Team!$A$5:$A$64,0),MAX($B6,Einstellungen!$B$3)-Einstellungen!$B$3,1,MIN($C6,Einstellungen!$B$4)-MAX($B6,Einstellungen!$B$3)+1)>=2)),"?"))) -> 0 | J6: =IF($A6="","",IF(OR($B6="",$C6=""),"Von und Bis eintragen",IF($C6<$B6,"Bis liegt vor Von",IF(ISNA(MATCH($A6,Team!$A$5:$A$64,0)),"Name fehlt im Blatt Team",IF(N($H6)+N($I6)>0,"Engpass – bitte absprechen",IF(OR($B6<Einstellungen!$B$3,$C6>Einstellungen!$B$4),"Teils außerhalb des Planungszeitraums","ok")))))) -> ok
A7: Beispiel David | B7: 46580 | C7: 46598 | D7: Wunsch | F7: =IF($A7="","",IFERROR(INDEX(Team!$B$5:$B$64,MATCH($A7,Team!$A$5:$A$64,0)),"?")) -> Musiktherapie | G7: =IF(OR($A7="",$B7="",$C7="",$C7<$B7),"",NETWORKDAYS($B7,$C7,Einstellungen!$I$7:$I$40)) -> 15 | H7: =IF(OR($A7="",$B7="",$C7="",$C7<$B7),"",IF(MIN($C7,Einstellungen!$B$4)<MAX($B7,Einstellungen!$B$3),0,IFERROR(SUMPRODUCT(--(MOD(OFFSET(Konflikt!$G$4,MATCH($A7,Team!$A$5:$A$64,0),MAX($B7,Einstellungen!$B$3)-Einstellungen!$B$3,1,MIN($C7,Einstellungen!$B$4)-MAX($B7,Einstellungen!$B$3)+1),2)=1)),"?"))) -> 0 | I7: =IF(OR($A7="",$B7="",$C7="",$C7<$B7),"",IF(MIN($C7,Einstellungen!$B$4)<MAX($B7,Einstellungen!$B$3),0,IFERROR(SUMPRODUCT(--(OFFSET(Konflikt!$G$4,MATCH($A7,Team!$A$5:$A$64,0),MAX($B7,Einstellungen!$B$3)-Einstellungen!$B$3,1,MIN($C7,Einstellungen!$B$4)-MAX($B7,Einstellungen!$B$3)+1)>=2)),"?"))) -> 5 | J7: =IF($A7="","",IF(OR($B7="",$C7=""),"Von und Bis eintragen",IF($C7<$B7,"Bis liegt vor Von",IF(ISNA(MATCH($A7,Team!$A$5:$A$64,0)),"Name fehlt im Blatt Team",IF(N($H7)+N($I7)>0,"Engpass – bitte absprechen",IF(OR($B7<Einstellungen!$B$3,$C7>Einstellungen!$B$4),"Teils außerhalb des Planungszeitraums","ok")))))) -> Engpass – bitte absprechen
A8: Beispiel Finn | B8: 46587 | C8: 46598 | D8: Wunsch | E8: Station 1A wäre dann leer – klären | F8: =IF($A8="","",IFERROR(INDEX(Team!$B$5:$B$64,MATCH($A8,Team!$A$5:$A$64,0)),"?")) -> Bewegungstherapie | G8: =IF(OR($A8="",$B8="",$C8="",$C8<$B8),"",NETWORKDAYS($B8,$C8,Einstellungen!$I$7:$I$40)) -> 10 | H8: =IF(OR($A8="",$B8="",$C8="",$C8<$B8),"",IF(MIN($C8,Einstellungen!$B$4)<MAX($B8,Einstellungen!$B$3),0,IFERROR(SUMPRODUCT(--(MOD(OFFSET(Konflikt!$G$4,MATCH($A8,Team!$A$5:$A$64,0),MAX($B8,Einstellungen!$B$3)-Einstellungen!$B$3,1,MIN($C8,Einstellungen!$B$4)-MAX($B8,Einstellungen!$B$3)+1),2)=1)),"?"))) -> 0 | I8: =IF(OR($A8="",$B8="",$C8="",$C8<$B8),"",IF(MIN($C8,Einstellungen!$B$4)<MAX($B8,Einstellungen!$B$3),0,IFERROR(SUMPRODUCT(--(OFFSET(Konflikt!$G$4,MATCH($A8,Team!$A$5:$A$64,0),MAX($B8,Einstellungen!$B$3)-Einstellungen!$B$3,1,MIN($C8,Einstellungen!$B$4)-MAX($B8,Einstellungen!$B$3)+1)>=2)),"?"))) -> 5 | J8: =IF($A8="","",IF(OR($B8="",$C8=""),"Von und Bis eintragen",IF($C8<$B8,"Bis liegt vor Von",IF(ISNA(MATCH($A8,Team!$A$5:$A$64,0)),"Name fehlt im Blatt Team",IF(N($H8)+N($I8)>0,"Engpass – bitte absprechen",IF(OR($B8<Einstellungen!$B$3,$C8>Einstellungen!$B$4),"Teils außerhalb des Planungszeitraums","ok")))))) -> Engpass – bitte absprechen
A9: Beispiel Eva | B9: 46671 | C9: 46675 | D9: eingereicht | F9: =IF($A9="","",IFERROR(INDEX(Team!$B$5:$B$64,MATCH($A9,Team!$A$5:$A$64,0)),"?")) -> Musiktherapie | G9: =IF(OR($A9="",$B9="",$C9="",$C9<$B9),"",NETWORKDAYS($B9,$C9,Einstellungen!$I$7:$I$40)) -> 5 | H9: =IF(OR($A9="",$B9="",$C9="",$C9<$B9),"",IF(MIN($C9,Einstellungen!$B$4)<MAX($B9,Einstellungen!$B$3),0,IFERROR(SUMPRODUCT(--(MOD(OFFSET(Konflikt!$G$4,MATCH($A9,Team!$A$5:$A$64,0),MAX($B9,Einstellungen!$B$3)-Einstellungen!$B$3,1,MIN($C9,Einstellungen!$B$4)-MAX($B9,Einstellungen!$B$3)+1),2)=1)),"?"))) -> 0 | I9: =IF(OR($A9="",$B9="",$C9="",$C9<$B9),"",IF(MIN($C9,Einstellungen!$B$4)<MAX($B9,Einstellungen!$B$3),0,IFERROR(SUMPRODUCT(--(OFFSET(Konflikt!$G$4,MATCH($A9,Team!$A$5:$A$64,0),MAX($B9,Einstellungen!$B$3)-Einstellungen!$B$3,1,MIN($C9,Einstellungen!$B$4)-MAX($B9,Einstellungen!$B$3)+1)>=2)),"?"))) -> 0 | J9: =IF($A9="","",IF(OR($B9="",$C9=""),"Von und Bis eintragen",IF($C9<$B9,"Bis liegt vor Von",IF(ISNA(MATCH($A9,Team!$A$5:$A$64,0)),"Name fehlt im Blatt Team",IF(N($H9)+N($I9)>0,"Engpass – bitte absprechen",IF(OR($B9<Einstellungen!$B$3,$C9>Einstellungen!$B$4),"Teils außerhalb des Planungszeitraums","ok")))))) -> ok
F10: =IF($A10="","",IFERROR(INDEX(Team!$B$5:$B$64,MATCH($A10,Team!$A$5:$A$64,0)),"?")) | G10: =IF(OR($A10="",$B10="",$C10="",$C10<$B10),"",NETWORKDAYS($B10,$C10,Einstellungen!$I$7:$I$40)) | H10: =IF(OR($A10="",$B10="",$C10="",$C10<$B10),"",IF(MIN($C10,Einstellungen!$B$4)<MAX($B10,Einstellungen!$B$3),0,IFERROR(SUMPRODUCT(--(MOD(OFFSET(Konflikt!$G$4,MATCH($A10,Team!$A$5:$A$64,0),MAX($B10,Einstellungen!$B$3)-Einstellungen!$B$3,1,MIN($C10,Einstellungen!$B$4)-MAX($B10,Einstellungen!$B$3)+1),2)=1)),"?"))) | I10: =IF(OR($A10="",$B10="",$C10="",$C10<$B10),"",IF(MIN($C10,Einstellungen!$B$4)<MAX($B10,Einstellungen!$B$3),0,IFERROR(SUMPRODUCT(--(OFFSET(Konflikt!$G$4,MATCH($A10,Team!$A$5:$A$64,0),MAX($B10,Einstellungen!$B$3)-Einstellungen!$B$3,1,MIN($C10,Einstellungen!$B$4)-MAX($B10,Einstellungen!$B$3)+1)>=2)),"?"))) | J10: =IF($A10="","",IF(OR($B10="",$C10=""),"Von und Bis eintragen",IF($C10<$B10,"Bis liegt vor Von",IF(ISNA(MATCH($A10,Team!$A$5:$A$64,0)),"Name fehlt im Blatt Team",IF(N($H10)+N($I10)>0,"Engpass – bitte absprechen",IF(OR($B10<Einstellungen!$B$3,$C10>Einstellungen!$B$4),"Teils außerhalb des Planungszeitraums","ok"))))))
F11: =IF($A11="","",IFERROR(INDEX(Team!$B$5:$B$64,MATCH($A11,Team!$A$5:$A$64,0)),"?")) | G11: =IF(OR($A11="",$B11="",$C11="",$C11<$B11),"",NETWORKDAYS($B11,$C11,Einstellungen!$I$7:$I$40)) | H11: =IF(OR($A11="",$B11="",$C11="",$C11<$B11),"",IF(MIN($C11,Einstellungen!$B$4)<MAX($B11,Einstellungen!$B$3),0,IFERROR(SUMPRODUCT(--(MOD(OFFSET(Konflikt!$G$4,MATCH($A11,Team!$A$5:$A$64,0),MAX($B11,Einstellungen!$B$3)-Einstellungen!$B$3,1,MIN($C11,Einstellungen!$B$4)-MAX($B11,Einstellungen!$B$3)+1),2)=1)),"?"))) | I11: =IF(OR($A11="",$B11="",$C11="",$C11<$B11),"",IF(MIN($C11,Einstellungen!$B$4)<MAX($B11,Einstellungen!$B$3),0,IFERROR(SUMPRODUCT(--(OFFSET(Konflikt!$G$4,MATCH($A11,Team!$A$5:$A$64,0),MAX($B11,Einstellungen!$B$3)-Einstellungen!$B$3,1,MIN($C11,Einstellungen!$B$4)-MAX($B11,Einstellungen!$B$3)+1)>=2)),"?"))) | J11: =IF($A11="","",IF(OR($B11="",$C11=""),"Von und Bis eintragen",IF($C11<$B11,"Bis liegt vor Von",IF(ISNA(MATCH($A11,Team!$A$5:$A$64,0)),"Name fehlt im Blatt Team",IF(N($H11)+N($I11)>0,"Engpass – bitte absprechen",IF(OR($B11<Einstellungen!$B$3,$C11>Einstellungen!$B$4),"Teils außerhalb des Planungszeitraums","ok"))))))
F12: =IF($A12="","",IFERROR(INDEX(Team!$B$5:$B$64,MATCH($A12,Team!$A$5:$A$64,0)),"?")) | G12: =IF(OR($A12="",$B12="",$C12="",$C12<$B12),"",NETWORKDAYS($B12,$C12,Einstellungen!$I$7:$I$40)) | H12: =IF(OR($A12="",$B12="",$C12="",$C12<$B12),"",IF(MIN($C12,Einstellungen!$B$4)<MAX($B12,Einstellungen!$B$3),0,IFERROR(SUMPRODUCT(--(MOD(OFFSET(Konflikt!$G$4,MATCH($A12,Team!$A$5:$A$64,0),MAX($B12,Einstellungen!$B$3)-Einstellungen!$B$3,1,MIN($C12,Einstellungen!$B$4)-MAX($B12,Einstellungen!$B$3)+1),2)=1)),"?"))) | I12: =IF(OR($A12="",$B12="",$C12="",$C12<$B12),"",IF(MIN($C12,Einstellungen!$B$4)<MAX($B12,Einstellungen!$B$3),0,IFERROR(SUMPRODUCT(--(OFFSET(Konflikt!$G$4,MATCH($A12,Team!$A$5:$A$64,0),MAX($B12,Einstellungen!$B$3)-Einstellungen!$B$3,1,MIN($C12,Einstellungen!$B$4)-MAX($B12,Einstellungen!$B$3)+1)>=2)),"?"))) | J12: =IF($A12="","",IF(OR($B12="",$C12=""),"Von und Bis eintragen",IF($C12<$B12,"Bis liegt vor Von",IF(ISNA(MATCH($A12,Team!$A$5:$A$64,0)),"Name fehlt im Blatt Team",IF(N($H12)+N($I12)>0,"Engpass – bitte absprechen",IF(OR($B12<Einstellungen!$B$3,$C12>Einstellungen!$B$4),"Teils außerhalb des Planungszeitraums","ok"))))))
F13: =IF($A13="","",IFERROR(INDEX(Team!$B$5:$B$64,MATCH($A13,Team!$A$5:$A$64,0)),"?")) | G13: =IF(OR($A13="",$B13="",$C13="",$C13<$B13),"",NETWORKDAYS($B13,$C13,Einstellungen!$I$7:$I$40)) | H13: =IF(OR($A13="",$B13="",$C13="",$C13<$B13),"",IF(MIN($C13,Einstellungen!$B$4)<MAX($B13,Einstellungen!$B$3),0,IFERROR(SUMPRODUCT(--(MOD(OFFSET(Konflikt!$G$4,MATCH($A13,Team!$A$5:$A$64,0),MAX($B13,Einstellungen!$B$3)-Einstellungen!$B$3,1,MIN($C13,Einstellungen!$B$4)-MAX($B13,Einstellungen!$B$3)+1),2)=1)),"?"))) | I13: =IF(OR($A13="",$B13="",$C13="",$C13<$B13),"",IF(MIN($C13,Einstellungen!$B$4)<MAX($B13,Einstellungen!$B$3),0,IFERROR(SUMPRODUCT(--(OFFSET(Konflikt!$G$4,MATCH($A13,Team!$A$5:$A$64,0),MAX($B13,Einstellungen!$B$3)-Einstellungen!$B$3,1,MIN($C13,Einstellungen!$B$4)-MAX($B13,Einstellungen!$B$3)+1)>=2)),"?"))) | J13: =IF($A13="","",IF(OR($B13="",$C13=""),"Von und Bis eintragen",IF($C13<$B13,"Bis liegt vor Von",IF(ISNA(MATCH($A13,Team!$A$5:$A$64,0)),"Name fehlt im Blatt Team",IF(N($H13)+N($I13)>0,"Engpass – bitte absprechen",IF(OR($B13<Einstellungen!$B$3,$C13>Einstellungen!$B$4),"Teils außerhalb des Planungszeitraums","ok"))))))
F14: =IF($A14="","",IFERROR(INDEX(Team!$B$5:$B$64,MATCH($A14,Team!$A$5:$A$64,0)),"?")) | G14: =IF(OR($A14="",$B14="",$C14="",$C14<$B14),"",NETWORKDAYS($B14,$C14,Einstellungen!$I$7:$I$40)) | H14: =IF(OR($A14="",$B14="",$C14="",$C14<$B14),"",IF(MIN($C14,Einstellungen!$B$4)<MAX($B14,Einstellungen!$B$3),0,IFERROR(SUMPRODUCT(--(MOD(OFFSET(Konflikt!$G$4,MATCH($A14,Team!$A$5:$A$64,0),MAX($B14,Einstellungen!$B$3)-Einstellungen!$B$3,1,MIN($C14,Einstellungen!$B$4)-MAX($B14,Einstellungen!$B$3)+1),2)=1)),"?"))) | I14: =IF(OR($A14="",$B14="",$C14="",$C14<$B14),"",IF(MIN($C14,Einstellungen!$B$4)<MAX($B14,Einstellungen!$B$3),0,IFERROR(SUMPRODUCT(--(OFFSET(Konflikt!$G$4,MATCH($A14,Team!$A$5:$A$64,0),MAX($B14,Einstellungen!$B$3)-Einstellungen!$B$3,1,MIN($C14,Einstellungen!$B$4)-MAX($B14,Einstellungen!$B$3)+1)>=2)),"?"))) | J14: =IF($A14="","",IF(OR($B14="",$C14=""),"Von und Bis eintragen",IF($C14<$B14,"Bis liegt vor Von",IF(ISNA(MATCH($A14,Team!$A$5:$A$64,0)),"Name fehlt im Blatt Team",IF(N($H14)+N($I14)>0,"Engpass – bitte absprechen",IF(OR($B14<Einstellungen!$B$3,$C14>Einstellungen!$B$4),"Teils außerhalb des Planungszeitraums","ok"))))))
F15: =IF($A15="","",IFERROR(INDEX(Team!$B$5:$B$64,MATCH($A15,Team!$A$5:$A$64,0)),"?")) | G15: =IF(OR($A15="",$B15="",$C15="",$C15<$B15),"",NETWORKDAYS($B15,$C15,Einstellungen!$I$7:$I$40)) | H15: =IF(OR($A15="",$B15="",$C15="",$C15<$B15),"",IF(MIN($C15,Einstellungen!$B$4)<MAX($B15,Einstellungen!$B$3),0,IFERROR(SUMPRODUCT(--(MOD(OFFSET(Konflikt!$G$4,MATCH($A15,Team!$A$5:$A$64,0),MAX($B15,Einstellungen!$B$3)-Einstellungen!$B$3,1,MIN($C15,Einstellungen!$B$4)-MAX($B15,Einstellungen!$B$3)+1),2)=1)),"?"))) | I15: =IF(OR($A15="",$B15="",$C15="",$C15<$B15),"",IF(MIN($C15,Einstellungen!$B$4)<MAX($B15,Einstellungen!$B$3),0,IFERROR(SUMPRODUCT(--(OFFSET(Konflikt!$G$4,MATCH($A15,Team!$A$5:$A$64,0),MAX($B15,Einstellungen!$B$3)-Einstellungen!$B$3,1,MIN($C15,Einstellungen!$B$4)-MAX($B15,Einstellungen!$B$3)+1)>=2)),"?"))) | J15: =IF($A15="","",IF(OR($B15="",$C15=""),"Von und Bis eintragen",IF($C15<$B15,"Bis liegt vor Von",IF(ISNA(MATCH($A15,Team!$A$5:$A$64,0)),"Name fehlt im Blatt Team",IF(N($H15)+N($I15)>0,"Engpass – bitte absprechen",IF(OR($B15<Einstellungen!$B$3,$C15>Einstellungen!$B$4),"Teils außerhalb des Planungszeitraums","ok"))))))
F16: =IF($A16="","",IFERROR(INDEX(Team!$B$5:$B$64,MATCH($A16,Team!$A$5:$A$64,0)),"?")) | G16: =IF(OR($A16="",$B16="",$C16="",$C16<$B16),"",NETWORKDAYS($B16,$C16,Einstellungen!$I$7:$I$40)) | H16: =IF(OR($A16="",$B16="",$C16="",$C16<$B16),"",IF(MIN($C16,Einstellungen!$B$4)<MAX($B16,Einstellungen!$B$3),0,IFERROR(SUMPRODUCT(--(MOD(OFFSET(Konflikt!$G$4,MATCH($A16,Team!$A$5:$A$64,0),MAX($B16,Einstellungen!$B$3)-Einstellungen!$B$3,1,MIN($C16,Einstellungen!$B$4)-MAX($B16,Einstellungen!$B$3)+1),2)=1)),"?"))) | I16: =IF(OR($A16="",$B16="",$C16="",$C16<$B16),"",IF(MIN($C16,Einstellungen!$B$4)<MAX($B16,Einstellungen!$B$3),0,IFERROR(SUMPRODUCT(--(OFFSET(Konflikt!$G$4,MATCH($A16,Team!$A$5:$A$64,0),MAX($B16,Einstellungen!$B$3)-Einstellungen!$B$3,1,MIN($C16,Einstellungen!$B$4)-MAX($B16,Einstellungen!$B$3)+1)>=2)),"?"))) | J16: =IF($A16="","",IF(OR($B16="",$C16=""),"Von und Bis eintragen",IF($C16<$B16,"Bis liegt vor Von",IF(ISNA(MATCH($A16,Team!$A$5:$A$64,0)),"Name fehlt im Blatt Team",IF(N($H16)+N($I16)>0,"Engpass – bitte absprechen",IF(OR($B16<Einstellungen!$B$3,$C16>Einstellungen!$B$4),"Teils außerhalb des Planungszeitraums","ok"))))))
F17: =IF($A17="","",IFERROR(INDEX(Team!$B$5:$B$64,MATCH($A17,Team!$A$5:$A$64,0)),"?")) | G17: =IF(OR($A17="",$B17="",$C17="",$C17<$B17),"",NETWORKDAYS($B17,$C17,Einstellungen!$I$7:$I$40)) | H17: =IF(OR($A17="",$B17="",$C17="",$C17<$B17),"",IF(MIN($C17,Einstellungen!$B$4)<MAX($B17,Einstellungen!$B$3),0,IFERROR(SUMPRODUCT(--(MOD(OFFSET(Konflikt!$G$4,MATCH($A17,Team!$A$5:$A$64,0),MAX($B17,Einstellungen!$B$3)-Einstellungen!$B$3,1,MIN($C17,Einstellungen!$B$4)-MAX($B17,Einstellungen!$B$3)+1),2)=1)),"?"))) | I17: =IF(OR($A17="",$B17="",$C17="",$C17<$B17),"",IF(MIN($C17,Einstellungen!$B$4)<MAX($B17,Einstellungen!$B$3),0,IFERROR(SUMPRODUCT(--(OFFSET(Konflikt!$G$4,MATCH($A17,Team!$A$5:$A$64,0),MAX($B17,Einstellungen!$B$3)-Einstellungen!$B$3,1,MIN($C17,Einstellungen!$B$4)-MAX($B17,Einstellungen!$B$3)+1)>=2)),"?"))) | J17: =IF($A17="","",IF(OR($B17="",$C17=""),"Von und Bis eintragen",IF($C17<$B17,"Bis liegt vor Von",IF(ISNA(MATCH($A17,Team!$A$5:$A$64,0)),"Name fehlt im Blatt Team",IF(N($H17)+N($I17)>0,"Engpass – bitte absprechen",IF(OR($B17<Einstellungen!$B$3,$C17>Einstellungen!$B$4),"Teils außerhalb des Planungszeitraums","ok"))))))
F18: =IF($A18="","",IFERROR(INDEX(Team!$B$5:$B$64,MATCH($A18,Team!$A$5:$A$64,0)),"?")) | G18: =IF(OR($A18="",$B18="",$C18="",$C18<$B18),"",NETWORKDAYS($B18,$C18,Einstellungen!$I$7:$I$40)) | H18: =IF(OR($A18="",$B18="",$C18="",$C18<$B18),"",IF(MIN($C18,Einstellungen!$B$4)<MAX($B18,Einstellungen!$B$3),0,IFERROR(SUMPRODUCT(--(MOD(OFFSET(Konflikt!$G$4,MATCH($A18,Team!$A$5:$A$64,0),MAX($B18,Einstellungen!$B$3)-Einstellungen!$B$3,1,MIN($C18,Einstellungen!$B$4)-MAX($B18,Einstellungen!$B$3)+1),2)=1)),"?"))) | I18: =IF(OR($A18="",$B18="",$C18="",$C18<$B18),"",IF(MIN($C18,Einstellungen!$B$4)<MAX($B18,Einstellungen!$B$3),0,IFERROR(SUMPRODUCT(--(OFFSET(Konflikt!$G$4,MATCH($A18,Team!$A$5:$A$64,0),MAX($B18,Einstellungen!$B$3)-Einstellungen!$B$3,1,MIN($C18,Einstellungen!$B$4)-MAX($B18,Einstellungen!$B$3)+1)>=2)),"?"))) | J18: =IF($A18="","",IF(OR($B18="",$C18=""),"Von und Bis eintragen",IF($C18<$B18,"Bis liegt vor Von",IF(ISNA(MATCH($A18,Team!$A$5:$A$64,0)),"Name fehlt im Blatt Team",IF(N($H18)+N($I18)>0,"Engpass – bitte absprechen",IF(OR($B18<Einstellungen!$B$3,$C18>Einstellungen!$B$4),"Teils außerhalb des Planungszeitraums","ok"))))))
F19: =IF($A19="","",IFERROR(INDEX(Team!$B$5:$B$64,MATCH($A19,Team!$A$5:$A$64,0)),"?")) | G19: =IF(OR($A19="",$B19="",$C19="",$C19<$B19),"",NETWORKDAYS($B19,$C19,Einstellungen!$I$7:$I$40)) | H19: =IF(OR($A19="",$B19="",$C19="",$C19<$B19),"",IF(MIN($C19,Einstellungen!$B$4)<MAX($B19,Einstellungen!$B$3),0,IFERROR(SUMPRODUCT(--(MOD(OFFSET(Konflikt!$G$4,MATCH($A19,Team!$A$5:$A$64,0),MAX($B19,Einstellungen!$B$3)-Einstellungen!$B$3,1,MIN($C19,Einstellungen!$B$4)-MAX($B19,Einstellungen!$B$3)+1),2)=1)),"?"))) | I19: =IF(OR($A19="",$B19="",$C19="",$C19<$B19),"",IF(MIN($C19,Einstellungen!$B$4)<MAX($B19,Einstellungen!$B$3),0,IFERROR(SUMPRODUCT(--(OFFSET(Konflikt!$G$4,MATCH($A19,Team!$A$5:$A$64,0),MAX($B19,Einstellungen!$B$3)-Einstellungen!$B$3,1,MIN($C19,Einstellungen!$B$4)-MAX($B19,Einstellungen!$B$3)+1)>=2)),"?"))) | J19: =IF($A19="","",IF(OR($B19="",$C19=""),"Von und Bis eintragen",IF($C19<$B19,"Bis liegt vor Von",IF(ISNA(MATCH($A19,Team!$A$5:$A$64,0)),"Name fehlt im Blatt Team",IF(N($H19)+N($I19)>0,"Engpass – bitte absprechen",IF(OR($B19<Einstellungen!$B$3,$C19>Einstellungen!$B$4),"Teils außerhalb des Planungszeitraums","ok"))))))
F20: =IF($A20="","",IFERROR(INDEX(Team!$B$5:$B$64,MATCH($A20,Team!$A$5:$A$64,0)),"?")) | G20: =IF(OR($A20="",$B20="",$C20="",$C20<$B20),"",NETWORKDAYS($B20,$C20,Einstellungen!$I$7:$I$40)) | H20: =IF(OR($A20="",$B20="",$C20="",$C20<$B20),"",IF(MIN($C20,Einstellungen!$B$4)<MAX($B20,Einstellungen!$B$3),0,IFERROR(SUMPRODUCT(--(MOD(OFFSET(Konflikt!$G$4,MATCH($A20,Team!$A$5:$A$64,0),MAX($B20,Einstellungen!$B$3)-Einstellungen!$B$3,1,MIN($C20,Einstellungen!$B$4)-MAX($B20,Einstellungen!$B$3)+1),2)=1)),"?"))) | I20: =IF(OR($A20="",$B20="",$C20="",$C20<$B20),"",IF(MIN($C20,Einstellungen!$B$4)<MAX($B20,Einstellungen!$B$3),0,IFERROR(SUMPRODUCT(--(OFFSET(Konflikt!$G$4,MATCH($A20,Team!$A$5:$A$64,0),MAX($B20,Einstellungen!$B$3)-Einstellungen!$B$3,1,MIN($C20,Einstellungen!$B$4)-MAX($B20,Einstellungen!$B$3)+1)>=2)),"?"))) | J20: =IF($A20="","",IF(OR($B20="",$C20=""),"Von und Bis eintragen",IF($C20<$B20,"Bis liegt vor Von",IF(ISNA(MATCH($A20,Team!$A$5:$A$64,0)),"Name fehlt im Blatt Team",IF(N($H20)+N($I20)>0,"Engpass – bitte absprechen",IF(OR($B20<Einstellungen!$B$3,$C20>Einstellungen!$B$4),"Teils außerhalb des Planungszeitraums","ok"))))))
F21: =IF($A21="","",IFERROR(INDEX(Team!$B$5:$B$64,MATCH($A21,Team!$A$5:$A$64,0)),"?")) | G21: =IF(OR($A21="",$B21="",$C21="",$C21<$B21),"",NETWORKDAYS($B21,$C21,Einstellungen!$I$7:$I$40)) | H21: =IF(OR($A21="",$B21="",$C21="",$C21<$B21),"",IF(MIN($C21,Einstellungen!$B$4)<MAX($B21,Einstellungen!$B$3),0,IFERROR(SUMPRODUCT(--(MOD(OFFSET(Konflikt!$G$4,MATCH($A21,Team!$A$5:$A$64,0),MAX($B21,Einstellungen!$B$3)-Einstellungen!$B$3,1,MIN($C21,Einstellungen!$B$4)-MAX($B21,Einstellungen!$B$3)+1),2)=1)),"?"))) | I21: =IF(OR($A21="",$B21="",$C21="",$C21<$B21),"",IF(MIN($C21,Einstellungen!$B$4)<MAX($B21,Einstellungen!$B$3),0,IFERROR(SUMPRODUCT(--(OFFSET(Konflikt!$G$4,MATCH($A21,Team!$A$5:$A$64,0),MAX($B21,Einstellungen!$B$3)-Einstellungen!$B$3,1,MIN($C21,Einstellungen!$B$4)-MAX($B21,Einstellungen!$B$3)+1)>=2)),"?"))) | J21: =IF($A21="","",IF(OR($B21="",$C21=""),"Von und Bis eintragen",IF($C21<$B21,"Bis liegt vor Von",IF(ISNA(MATCH($A21,Team!$A$5:$A$64,0)),"Name fehlt im Blatt Team",IF(N($H21)+N($I21)>0,"Engpass – bitte absprechen",IF(OR($B21<Einstellungen!$B$3,$C21>Einstellungen!$B$4),"Teils außerhalb des Planungszeitraums","ok"))))))
... F604: =IF($A604="","",IFERROR(INDEX(Team!$B$5:$B$64,MATCH($A604,Team!$A$5:$A$64,0)),"?")) | G604: =IF(OR($A604="",$B604="",$C604="",$C604<$B604),"",NETWORKDAYS($B604,$C604,Einstellungen!$I$7:$I$40)) | H604: =IF(OR($A604="",$B604="",$C604="",$C604<$B604),"",IF(MIN($C604,Einstellungen!$B$4)<MAX($B604,Einstellungen!$B$3),0,IFERROR(SUMPRODUCT(--(MOD(OFFSET(Konflikt!$G$4,MATCH($A604,Team!$A$5:$A$64,0),MAX($B604,Einstellungen!$B$3)-Einstellungen!$B$3,1,MIN($C604,Einstellungen!$B$4)-MAX($B604,Einstellungen!$B$3)+1),2)=1)),"?"))) | I604: =IF(OR($A604="",$B604="",$C604="",$C604<$B604),"",IF(MIN($C604,Einstellungen!$B$4)<MAX($B604,Einstellungen!$B$3),0,IFERROR(SUMPRODUCT(--(OFFSET(Konflikt!$G$4,MATCH($A604,Team!$A$5:$A$64,0),MAX($B604,Einstellungen!$B$3)-Einstellungen!$B$3,1,MIN($C604,Einstellungen!$B$4)-MAX($B604,Einstellungen!$B$3)+1)>=2)),"?"))) | J604: =IF($A604="","",IF(OR($B604="",$C604=""),"Von und Bis eintragen",IF($C604<$B604,"Bis liegt vor Von",IF(ISNA(MATCH($A604,Team!$A$5:$A$64,0)),"Name fehlt im Blatt Team",IF(N($H604)+N($I604)>0,"Engpass – bitte absprechen",IF(OR($B604<Einstellungen!$B$3,$C604>Einstellungen!$B$4),"Teils außerhalb des Planungszeitraums","ok"))))))

Sheet Kalender
A1: Kalender – wer ist wann weg?
A2: Nur ansehen. Einträge im Blatt »Urlaub«. | G2: =IF(OR(DAY(G3)=1,COLUMN()=7),CHOOSE(MONTH(G3),"Jan","Feb","Mär","Apr","Mai","Jun","Jul","Aug","Sep","Okt","Nov","Dez")&" "&YEAR(G3),"") -> Jan 2027 | H2: =IF(OR(DAY(H3)=1,COLUMN()=7),CHOOSE(MONTH(H3),"Jan","Feb","Mär","Apr","Mai","Jun","Jul","Aug","Sep","Okt","Nov","Dez")&" "&YEAR(H3),"") | I2: =IF(OR(DAY(I3)=1,COLUMN()=7),CHOOSE(MONTH(I3),"Jan","Feb","Mär","Apr","Mai","Jun","Jul","Aug","Sep","Okt","Nov","Dez")&" "&YEAR(I3),"") | J2: =IF(OR(DAY(J3)=1,COLUMN()=7),CHOOSE(MONTH(J3),"Jan","Feb","Mär","Apr","Mai","Jun","Jul","Aug","Sep","Okt","Nov","Dez")&" "&YEAR(J3),"") | K2: =IF(OR(DAY(K3)=1,COLUMN()=7),CHOOSE(MONTH(K3),"Jan","Feb","Mär","Apr","Mai","Jun","Jul","Aug","Sep","Okt","Nov","Dez")&" "&YEAR(K3),"") | L2: =IF(OR(DAY(L3)=1,COLUMN()=7),CHOOSE(MONTH(L3),"Jan","Feb","Mär","Apr","Mai","Jun","Jul","Aug","Sep","Okt","Nov","Dez")&" "&YEAR(L3),"") | M2: =IF(OR(DAY(M3)=1,COLUMN()=7),CHOOSE(MONTH(M3),"Jan","Feb","Mär","Apr","Mai","Jun","Jul","Aug","Sep","Okt","Nov","Dez")&" "&YEAR(M3),"") | N2: =IF(OR(DAY(N3)=1,COLUMN()=7),CHOOSE(MONTH(N3),"Jan","Feb","Mär","Apr","Mai","Jun","Jul","Aug","Sep","Okt","Nov","Dez")&" "&YEAR(N3),"") | ... NH2: =IF(OR(DAY(NH3)=1,COLUMN()=7),CHOOSE(MONTH(NH3),"Jan","Feb","Mär","Apr","Mai","Jun","Jul","Aug","Sep","Okt","Nov","Dez")&" "&YEAR(NH3),"") -> Jan 2028
A3: Monat / Tag → | G3: =Einstellungen!$B$3+0 -> 46388 | H3: =Einstellungen!$B$3+1 -> 46389 | I3: =Einstellungen!$B$3+2 -> 46390 | J3: =Einstellungen!$B$3+3 -> 46391 | K3: =Einstellungen!$B$3+4 -> 46392 | L3: =Einstellungen!$B$3+5 -> 46393 | M3: =Einstellungen!$B$3+6 -> 46394 | N3: =Einstellungen!$B$3+7 -> 46395 | O3: =Einstellungen!$B$3+8 -> 46396 | P3: =Einstellungen!$B$3+9 -> 46397 | Q3: =Einstellungen!$B$3+10 -> 46398 | R3: =Einstellungen!$B$3+11 -> 46399 | S3: =Einstellungen!$B$3+12 -> 46400 | T3: =Einstellungen!$B$3+13 -> 46401 | U3: =Einstellungen!$B$3+14 -> 46402 | V3: =Einstellungen!$B$3+15 -> 46403 | W3: =Einstellungen!$B$3+16 -> 46404 | X3: =Einstellungen!$B$3+17 -> 46405 | Y3: =Einstellungen!$B$3+18 -> 46406 | Z3: =Einstellungen!$B$3+19 -> 46407 | AA3: =Einstellungen!$B$3+20 -> 46408 | AB3: =Einstellungen!$B$3+21 -> 46409 | AC3: =Einstellungen!$B$3+22 -> 46410 | AD3: =Einstellungen!$B$3+23 -> 46411 | AE3: =Einstellungen!$B$3+24 -> 46412 | AF3: =Einstellungen!$B$3+25 -> 46413 | AG3: =Einstellungen!$B$3+26 -> 46414 | AH3: =Einstellungen!$B$3+27 -> 46415 | AI3: =Einstellungen!$B$3+28 -> 46416 | AJ3: =Einstellungen!$B$3+29 -> 46417 | AK3: =Einstellungen!$B$3+30 -> 46418 | AL3: =Einstellungen!$B$3+31 -> 46419 | AM3: =Einstellungen!$B$3+32 -> 46420 | AN3: =Einstellungen!$B$3+33 -> 46421 | AO3: =Einstellungen!$B$3+34 -> 46422 | AP3: =Einstellungen!$B$3+35 -> 46423 | AQ3: =Einstellungen!$B$3+36 -> 46424 | AR3: =Einstellungen!$B$3+37 -> 46425 | AS3: =Einstellungen!$B$3+38 -> 46426 | AT3: =Einstellungen!$B$3+39 -> 46427 | AU3: =Einstellungen!$B$3+40 -> 46428 | AV3: =Einstellungen!$B$3+41 -> 46429 | AW3: =Einstellungen!$B$3+42 -> 46430 | AX3: =Einstellungen!$B$3+43 -> 46431 | AY3: =Einstellungen!$B$3+44 -> 46432 | AZ3: =Einstellungen!$B$3+45 -> 46433 | BA3: =Einstellungen!$B$3+46 -> 46434 | BB3: =Einstellungen!$B$3+47 -> 46435 | BC3: =Einstellungen!$B$3+48 -> 46436 | BD3: =Einstellungen!$B$3+49 -> 46437 | BE3: =Einstellungen!$B$3+50 -> 46438 | BF3: =Einstellungen!$B$3+51 -> 46439 | BG3: =Einstellungen!$B$3+52 -> 46440 | BH3: =Einstellungen!$B$3+53 -> 46441 | BI3: =Einstellungen!$B$3+54 -> 46442 | BJ3: =Einstellungen!$B$3+55 -> 46443 | BK3: =Einstellungen!$B$3+56 -> 46444 | BL3: =Einstellungen!$B$3+57 -> 46445 | BM3: =Einstellungen!$B$3+58 -> 46446 | BN3: =Einstellungen!$B$3+59 -> 46447 | BO3: =Einstellungen!$B$3+60 -> 46448 | BP3: =Einstellungen!$B$3+61 -> 46449 | BQ3: =Einstellungen!$B$3+62 -> 46450 | BR3: =Einstellungen!$B$3+63 -> 46451 | BS3: =Einstellungen!$B$3+64 -> 46452 | BT3: =Einstellungen!$B$3+65 -> 46453 | BU3: =Einstellungen!$B$3+66 -> 46454 | BV3: =Einstellungen!$B$3+67 -> 46455 | BW3: =Einstellungen!$B$3+68 -> 46456 | BX3: =Einstellungen!$B$3+69 -> 46457 | BY3: =Einstellungen!$B$3+70 -> 46458 | BZ3: =Einstellungen!$B$3+71 -> 46459 | CA3: =Einstellungen!$B$3+72 -> 46460 | CB3: =Einstellungen!$B$3+73 -> 46461 | CC3: =Einstellungen!$B$3+74 -> 46462 | CD3: =Einstellungen!$B$3+75 -> 46463 | CE3: =Einstellungen!$B$3+76 -> 46464 | CF3: =Einstellungen!$B$3+77 -> 46465 | CG3: =Einstellungen!$B$3+78 -> 46466 | CH3: =Einstellungen!$B$3+79 -> 46467 | CI3: =Einstellungen!$B$3+80 -> 46468 | CJ3: =Einstellungen!$B$3+81 -> 46469 | CK3: =Einstellungen!$B$3+82 -> 46470 | CL3: =Einstellungen!$B$3+83 -> 46471 | CM3: =Einstellungen!$B$3+84 -> 46472 | CN3: =Einstellungen!$B$3+85 -> 46473 | CO3: =Einstellungen!$B$3+86 -> 46474 | CP3: =Einstellungen!$B$3+87 -> 46475 | CQ3: =Einstellungen!$B$3+88 -> 46476 | CR3: =Einstellungen!$B$3+89 -> 46477 | CS3: =Einstellungen!$B$3+90 -> 46478 | CT3: =Einstellungen!$B$3+91 -> 46479 | CU3: =Einstellungen!$B$3+92 -> 46480 | CV3: =Einstellungen!$B$3+93 -> 46481 | CW3: =Einstellungen!$B$3+94 -> 46482 | CX3: =Einstellungen!$B$3+95 -> 46483 | CY3: =Einstellungen!$B$3+96 -> 46484 | CZ3: =Einstellungen!$B$3+97 -> 46485 | DA3: =Einstellungen!$B$3+98 -> 46486 | DB3: =Einstellungen!$B$3+99 -> 46487 | DC3: =Einstellungen!$B$3+100 -> 46488 | DD3: =Einstellungen!$B$3+101 -> 46489 | DE3: =Einstellungen!$B$3+102 -> 46490 | DF3: =Einstellungen!$B$3+103 -> 46491 | DG3: =Einstellungen!$B$3+104 -> 46492 | DH3: =Einstellungen!$B$3+105 -> 46493 | DI3: =Einstellungen!$B$3+106 -> 46494 | DJ3: =Einstellungen!$B$3+107 -> 46495 | DK3: =Einstellungen!$B$3+108 -> 46496 | DL3: =Einstellungen!$B$3+109 -> 46497 | DM3: =Einstellungen!$B$3+110 -> 46498 | DN3: =Einstellungen!$B$3+111 -> 46499 | DO3: =Einstellungen!$B$3+112 -> 46500 | DP3: =Einstellungen!$B$3+113 -> 46501 | DQ3: =Einstellungen!$B$3+114 -> 46502 | DR3: =Einstellungen!$B$3+115 -> 46503 | DS3: =Einstellungen!$B$3+116 -> 46504 | DT3: =Einstellungen!$B$3+117 -> 46505 | DU3: =Einstellungen!$B$3+118 -> 46506 | DV3: =Einstellungen!$B$3+119 -> 46507 | DW3: =Einstellungen!$B$3+120 -> 46508 | DX3: =Einstellungen!$B$3+121 -> 46509 | DY3: =Einstellungen!$B$3+122 -> 46510 | DZ3: =Einstellungen!$B$3+123 -> 46511 | EA3: =Einstellungen!$B$3+124 -> 46512 | EB3: =Einstellungen!$B$3+125 -> 46513 | EC3: =Einstellungen!$B$3+126 -> 46514 | ED3: =Einstellungen!$B$3+127 -> 46515 | EE3: =Einstellungen!$B$3+128 -> 46516 | EF3: =Einstellungen!$B$3+129 -> 46517 | EG3: =Einstellungen!$B$3+130 -> 46518 | EH3: =Einstellungen!$B$3+131 -> 46519 | EI3: =Einstellungen!$B$3+132 -> 46520 | EJ3: =Einstellungen!$B$3+133 -> 46521 | EK3: =Einstellungen!$B$3+134 -> 46522 | EL3: =Einstellungen!$B$3+135 -> 46523 | EM3: =Einstellungen!$B$3+136 -> 46524 | EN3: =Einstellungen!$B$3+137 -> 46525 | EO3: =Einstellungen!$B$3+138 -> 46526 | EP3: =Einstellungen!$B$3+139 -> 46527 | EQ3: =Einstellungen!$B$3+140 -> 46528 | ER3: =Einstellungen!$B$3+141 -> 46529 | ES3: =Einstellungen!$B$3+142 -> 46530 | ET3: =Einstellungen!$B$3+143 -> 46531 | EU3: =Einstellungen!$B$3+144 -> 46532 | EV3: =Einstellungen!$B$3+145 -> 46533 | EW3: =Einstellungen!$B$3+146 -> 46534 | EX3: =Einstellungen!$B$3+147 -> 46535 | EY3: =Einstellungen!$B$3+148 -> 46536 | EZ3: =Einstellungen!$B$3+149 -> 46537 | FA3: =Einstellungen!$B$3+150 -> 46538 | FB3: =Einstellungen!$B$3+151 -> 46539 | FC3: =Einstellungen!$B$3+152 -> 46540 | FD3: =Einstellungen!$B$3+153 -> 46541 | FE3: =Einstellungen!$B$3+154 -> 46542 | FF3: =Einstellungen!$B$3+155 -> 46543 | FG3: =Einstellungen!$B$3+156 -> 46544 | FH3: =Einstellungen!$B$3+157 -> 46545 | FI3: =Einstellungen!$B$3+158 -> 46546 | FJ3: =Einstellungen!$B$3+159 -> 46547 | FK3: =Einstellungen!$B$3+160 -> 46548 | FL3: =Einstellungen!$B$3+161 -> 46549 | FM3: =Einstellungen!$B$3+162 -> 46550 | FN3: =Einstellungen!$B$3+163 -> 46551 | FO3: =Einstellungen!$B$3+164 -> 46552 | FP3: =Einstellungen!$B$3+165 -> 46553 | FQ3: =Einstellungen!$B$3+166 -> 46554 | FR3: =Einstellungen!$B$3+167 -> 46555 | FS3: =Einstellungen!$B$3+168 -> 46556 | FT3: =Einstellungen!$B$3+169 -> 46557 | FU3: =Einstellungen!$B$3+170 -> 46558 | FV3: =Einstellungen!$B$3+171 -> 46559 | FW3: =Einstellungen!$B$3+172 -> 46560 | FX3: =Einstellungen!$B$3+173 -> 46561 | FY3: =Einstellungen!$B$3+174 -> 46562 | FZ3: =Einstellungen!$B$3+175 -> 46563 | GA3: =Einstellungen!$B$3+176 -> 46564 | GB3: =Einstellungen!$B$3+177 -> 46565 | GC3: =Einstellungen!$B$3+178 -> 46566 | GD3: =Einstellungen!$B$3+179 -> 46567 | GE3: =Einstellungen!$B$3+180 -> 46568 | GF3: =Einstellungen!$B$3+181 -> 46569 | GG3: =Einstellungen!$B$3+182 -> 46570 | GH3: =Einstellungen!$B$3+183 -> 46571 | GI3: =Einstellungen!$B$3+184 -> 46572 | GJ3: =Einstellungen!$B$3+185 -> 46573 | GK3: =Einstellungen!$B$3+186 -> 46574 | GL3: =Einstellungen!$B$3+187 -> 46575 | GM3: =Einstellungen!$B$3+188 -> 46576 | GN3: =Einstellungen!$B$3+189 -> 46577 | GO3: =Einstellungen!$B$3+190 -> 46578 | GP3: =Einstellungen!$B$3+191 -> 46579 | GQ3: =Einstellungen!$B$3+192 -> 46580 | GR3: =Einstellungen!$B$3+193 -> 46581 | GS3: =Einstellungen!$B$3+194 -> 46582 | GT3: =Einstellungen!$B$3+195 -> 46583 | GU3: =Einstellungen!$B$3+196 -> 46584 | GV3: =Einstellungen!$B$3+197 -> 46585 | GW3: =Einstellungen!$B$3+198 -> 46586 | GX3: =Einstellungen!$B$3+199 -> 46587 | GY3: =Einstellungen!$B$3+200 -> 46588 | GZ3: =Einstellungen!$B$3+201 -> 46589 | HA3: =Einstellungen!$B$3+202 -> 46590 | HB3: =Einstellungen!$B$3+203 -> 46591 | HC3: =Einstellungen!$B$3+204 -> 46592 | HD3: =Einstellungen!$B$3+205 -> 46593 | HE3: =Einstellungen!$B$3+206 -> 46594 | HF3: =Einstellungen!$B$3+207 -> 46595 | HG3: =Einstellungen!$B$3+208 -> 46596 | HH3: =Einstellungen!$B$3+209 -> 46597 | HI3: =Einstellungen!$B$3+210 -> 46598 | HJ3: =Einstellungen!$B$3+211 -> 46599 | HK3: =Einstellungen!$B$3+212 -> 46600 | HL3: =Einstellungen!$B$3+213 -> 46601 | HM3: =Einstellungen!$B$3+214 -> 46602 | HN3: =Einstellungen!$B$3+215 -> 46603 | HO3: =Einstellungen!$B$3+216 -> 46604 | HP3: =Einstellungen!$B$3+217 -> 46605 | HQ3: =Einstellungen!$B$3+218 -> 46606 | HR3: =Einstellungen!$B$3+219 -> 46607 | HS3: =Einstellungen!$B$3+220 -> 46608 | HT3: =Einstellungen!$B$3+221 -> 46609 | HU3: =Einstellungen!$B$3+222 -> 46610 | HV3: =Einstellungen!$B$3+223 -> 46611 | HW3: =Einstellungen!$B$3+224 -> 46612 | HX3: =Einstellungen!$B$3+225 -> 46613 | HY3: =Einstellungen!$B$3+226 -> 46614 | HZ3: =Einstellungen!$B$3+227 -> 46615 | IA3: =Einstellungen!$B$3+228 -> 46616 | IB3: =Einstellungen!$B$3+229 -> 46617 | IC3: =Einstellungen!$B$3+230 -> 46618 | ID3: =Einstellungen!$B$3+231 -> 46619 | IE3: =Einstellungen!$B$3+232 -> 46620 | IF3: =Einstellungen!$B$3+233 -> 46621 | IG3: =Einstellungen!$B$3+234 -> 46622 | IH3: =Einstellungen!$B$3+235 -> 46623 | II3: =Einstellungen!$B$3+236 -> 46624 | IJ3: =Einstellungen!$B$3+237 -> 46625 | IK3: =Einstellungen!$B$3+238 -> 46626 | IL3: =Einstellungen!$B$3+239 -> 46627 | IM3: =Einstellungen!$B$3+240 -> 46628 | IN3: =Einstellungen!$B$3+241 -> 46629 | IO3: =Einstellungen!$B$3+242 -> 46630 | IP3: =Einstellungen!$B$3+243 -> 46631 | IQ3: =Einstellungen!$B$3+244 -> 46632 | IR3: =Einstellungen!$B$3+245 -> 46633 | IS3: =Einstellungen!$B$3+246 -> 46634 | IT3: =Einstellungen!$B$3+247 -> 46635 | IU3: =Einstellungen!$B$3+248 -> 46636 | IV3: =Einstellungen!$B$3+249 -> 46637 | IW3: =Einstellungen!$B$3+250 -> 46638 | IX3: =Einstellungen!$B$3+251 -> 46639 | IY3: =Einstellungen!$B$3+252 -> 46640 | IZ3: =Einstellungen!$B$3+253 -> 46641 | JA3: =Einstellungen!$B$3+254 -> 46642 | JB3: =Einstellungen!$B$3+255 -> 46643 | JC3: =Einstellungen!$B$3+256 -> 46644 | JD3: =Einstellungen!$B$3+257 -> 46645 | JE3: =Einstellungen!$B$3+258 -> 46646 | JF3: =Einstellungen!$B$3+259 -> 46647 | JG3: =Einstellungen!$B$3+260 -> 46648 | JH3: =Einstellungen!$B$3+261 -> 46649 | JI3: =Einstellungen!$B$3+262 -> 46650 | JJ3: =Einstellungen!$B$3+263 -> 46651 | JK3: =Einstellungen!$B$3+264 -> 46652 | JL3: =Einstellungen!$B$3+265 -> 46653 | JM3: =Einstellungen!$B$3+266 -> 46654 | JN3: =Einstellungen!$B$3+267 -> 46655 | JO3: =Einstellungen!$B$3+268 -> 46656 | JP3: =Einstellungen!$B$3+269 -> 46657 | JQ3: =Einstellungen!$B$3+270 -> 46658 | JR3: =Einstellungen!$B$3+271 -> 46659 | JS3: =Einstellungen!$B$3+272 -> 46660 | JT3: =Einstellungen!$B$3+273 -> 46661 | JU3: =Einstellungen!$B$3+274 -> 46662 | JV3: =Einstellungen!$B$3+275 -> 46663 | JW3: =Einstellungen!$B$3+276 -> 46664 | JX3: =Einstellungen!$B$3+277 -> 46665 | JY3: =Einstellungen!$B$3+278 -> 46666 | JZ3: =Einstellungen!$B$3+279 -> 46667 | KA3: =Einstellungen!$B$3+280 -> 46668 | KB3: =Einstellungen!$B$3+281 -> 46669 | KC3: =Einstellungen!$B$3+282 -> 46670 | KD3: =Einstellungen!$B$3+283 -> 46671 | KE3: =Einstellungen!$B$3+284 -> 46672 | KF3: =Einstellungen!$B$3+285 -> 46673 | KG3: =Einstellungen!$B$3+286 -> 46674 | KH3: =Einstellungen!$B$3+287 -> 46675 | KI3: =Einstellungen!$B$3+288 -> 46676 | KJ3: =Einstellungen!$B$3+289 -> 46677 | KK3: =Einstellungen!$B$3+290 -> 46678 | KL3: =Einstellungen!$B$3+291 -> 46679 | KM3: =Einstellungen!$B$3+292 -> 46680 | KN3: =Einstellungen!$B$3+293 -> 46681 | KO3: =Einstellungen!$B$3+294 -> 46682 | KP3: =Einstellungen!$B$3+295 -> 46683 | KQ3: =Einstellungen!$B$3+296 -> 46684 | KR3: =Einstellungen!$B$3+297 -> 46685 | KS3: =Einstellungen!$B$3+298 -> 46686 | KT3: =Einstellungen!$B$3+299 -> 46687 | KU3: =Einstellungen!$B$3+300 -> 46688 | KV3: =Einstellungen!$B$3+301 -> 46689 | KW3: =Einstellungen!$B$3+302 -> 46690 | KX3: =Einstellungen!$B$3+303 -> 46691 | KY3: =Einstellungen!$B$3+304 -> 46692 | KZ3: =Einstellungen!$B$3+305 -> 46693 | LA3: =Einstellungen!$B$3+306 -> 46694 | LB3: =Einstellungen!$B$3+307 -> 46695 | LC3: =Einstellungen!$B$3+308 -> 46696 | LD3: =Einstellungen!$B$3+309 -> 46697 | LE3: =Einstellungen!$B$3+310 -> 46698 | LF3: =Einstellungen!$B$3+311 -> 46699 | LG3: =Einstellungen!$B$3+312 -> 46700 | LH3: =Einstellungen!$B$3+313 -> 46701 | LI3: =Einstellungen!$B$3+314 -> 46702 | LJ3: =Einstellungen!$B$3+315 -> 46703 | LK3: =Einstellungen!$B$3+316 -> 46704 | LL3: =Einstellungen!$B$3+317 -> 46705 | LM3: =Einstellungen!$B$3+318 -> 46706 | LN3: =Einstellungen!$B$3+319 -> 46707 | LO3: =Einstellungen!$B$3+320 -> 46708 | LP3: =Einstellungen!$B$3+321 -> 46709 | LQ3: =Einstellungen!$B$3+322 -> 46710 | LR3: =Einstellungen!$B$3+323 -> 46711 | LS3: =Einstellungen!$B$3+324 -> 46712 | LT3: =Einstellungen!$B$3+325 -> 46713 | LU3: =Einstellungen!$B$3+326 -> 46714 | LV3: =Einstellungen!$B$3+327 -> 46715 | LW3: =Einstellungen!$B$3+328 -> 46716 | LX3: =Einstellungen!$B$3+329 -> 46717 | LY3: =Einstellungen!$B$3+330 -> 46718 | LZ3: =Einstellungen!$B$3+331 -> 46719 | MA3: =Einstellungen!$B$3+332 -> 46720 | MB3: =Einstellungen!$B$3+333 -> 46721 | MC3: =Einstellungen!$B$3+334 -> 46722 | MD3: =Einstellungen!$B$3+335 -> 46723 | ME3: =Einstellungen!$B$3+336 -> 46724 | MF3: =Einstellungen!$B$3+337 -> 46725 | MG3: =Einstellungen!$B$3+338 -> 46726 | MH3: =Einstellungen!$B$3+339 -> 46727 | MI3: =Einstellungen!$B$3+340 -> 46728 | MJ3: =Einstellungen!$B$3+341 -> 46729 | MK3: =Einstellungen!$B$3+342 -> 46730 | ML3: =Einstellungen!$B$3+343 -> 46731 | MM3: =Einstellungen!$B$3+344 -> 46732 | MN3: =Einstellungen!$B$3+345 -> 46733 | MO3: =Einstellungen!$B$3+346 -> 46734 | MP3: =Einstellungen!$B$3+347 -> 46735 | MQ3: =Einstellungen!$B$3+348 -> 46736 | MR3: =Einstellungen!$B$3+349 -> 46737 | MS3: =Einstellungen!$B$3+350 -> 46738 | MT3: =Einstellungen!$B$3+351 -> 46739 | MU3: =Einstellungen!$B$3+352 -> 46740 | MV3: =Einstellungen!$B$3+353 -> 46741 | MW3: =Einstellungen!$B$3+354 -> 46742 | MX3: =Einstellungen!$B$3+355 -> 46743 | MY3: =Einstellungen!$B$3+356 -> 46744 | MZ3: =Einstellungen!$B$3+357 -> 46745 | NA3: =Einstellungen!$B$3+358 -> 46746 | NB3: =Einstellungen!$B$3+359 -> 46747 | NC3: =Einstellungen!$B$3+360 -> 46748 | ND3: =Einstellungen!$B$3+361 -> 46749 | NE3: =Einstellungen!$B$3+362 -> 46750 | NF3: =Einstellungen!$B$3+363 -> 46751 | NG3: =Einstellungen!$B$3+364 -> 46752 | NH3: =Einstellungen!$B$3+365 -> 46753
A4: Name | B4: Fachrichtung | C4: St. 1 | D4: St. 2 | E4: St. 3 | F4: St. 4 | G4: =CHOOSE(WEEKDAY(G3,2),"Mo","Di","Mi","Do","Fr","Sa","So") -> Fr | H4: =CHOOSE(WEEKDAY(H3,2),"Mo","Di","Mi","Do","Fr","Sa","So") -> Sa | I4: =CHOOSE(WEEKDAY(I3,2),"Mo","Di","Mi","Do","Fr","Sa","So") -> So | J4: =CHOOSE(WEEKDAY(J3,2),"Mo","Di","Mi","Do","Fr","Sa","So") -> Mo | K4: =CHOOSE(WEEKDAY(K3,2),"Mo","Di","Mi","Do","Fr","Sa","So") -> Di | L4: =CHOOSE(WEEKDAY(L3,2),"Mo","Di","Mi","Do","Fr","Sa","So") -> Mi | M4: =CHOOSE(WEEKDAY(M3,2),"Mo","Di","Mi","Do","Fr","Sa","So") -> Do | N4: =CHOOSE(WEEKDAY(N3,2),"Mo","Di","Mi","Do","Fr","Sa","So") -> Fr | ... NH4: =CHOOSE(WEEKDAY(NH3,2),"Mo","Di","Mi","Do","Fr","Sa","So") -> Sa
A5: =IF(Team!A5="","",Team!A5) -> Beispiel Anna | B5: =IF(Team!B5="","",Team!B5) -> Ergotherapie | C5: =IF(Team!C5="","",Team!C5) -> Station 1A | D5: =IF(Team!D5="","",Team!D5) -> Station 1B | E5: =IF(Team!E5="","",Team!E5) | F5: =IF(Team!F5="","",Team!F5) | G5: =IF($A5="",0,IF(COUNTIFS(Urlaub!$A$5:$A$604,$A5,Urlaub!$B$5:$B$604,"<="&G$3,Urlaub!$C$5:$C$604,">="&G$3)>0,1,0)) -> 0 | H5: =IF($A5="",0,IF(COUNTIFS(Urlaub!$A$5:$A$604,$A5,Urlaub!$B$5:$B$604,"<="&H$3,Urlaub!$C$5:$C$604,">="&H$3)>0,1,0)) -> 0 | I5: =IF($A5="",0,IF(COUNTIFS(Urlaub!$A$5:$A$604,$A5,Urlaub!$B$5:$B$604,"<="&I$3,Urlaub!$C$5:$C$604,">="&I$3)>0,1,0)) -> 0 | J5: =IF($A5="",0,IF(COUNTIFS(Urlaub!$A$5:$A$604,$A5,Urlaub!$B$5:$B$604,"<="&J$3,Urlaub!$C$5:$C$604,">="&J$3)>0,1,0)) -> 0 | K5: =IF($A5="",0,IF(COUNTIFS(Urlaub!$A$5:$A$604,$A5,Urlaub!$B$5:$B$604,"<="&K$3,Urlaub!$C$5:$C$604,">="&K$3)>0,1,0)) -> 0 | L5: =IF($A5="",0,IF(COUNTIFS(Urlaub!$A$5:$A$604,$A5,Urlaub!$B$5:$B$604,"<="&L$3,Urlaub!$C$5:$C$604,">="&L$3)>0,1,0)) -> 0 | M5: =IF($A5="",0,IF(COUNTIFS(Urlaub!$A$5:$A$604,$A5,Urlaub!$B$5:$B$604,"<="&M$3,Urlaub!$C$5:$C$604,">="&M$3)>0,1,0)) -> 0 | N5: =IF($A5="",0,IF(COUNTIFS(Urlaub!$A$5:$A$604,$A5,Urlaub!$B$5:$B$604,"<="&N$3,Urlaub!$C$5:$C$604,">="&N$3)>0,1,0)) -> 0 | ... NH5: =IF($A5="",0,IF(COUNTIFS(Urlaub!$A$5:$A$604,$A5,Urlaub!$B$5:$B$604,"<="&NH$3,Urlaub!$C$5:$C$604,">="&NH$3)>0,1,0)) -> 0
A6: =IF(Team!A6="","",Team!A6) -> Beispiel Ben | B6: =IF(Team!B6="","",Team!B6) -> Ergotherapie | C6: =IF(Team!C6="","",Team!C6) -> Station 2A | D6: =IF(Team!D6="","",Team!D6) | E6: =IF(Team!E6="","",Team!E6) | F6: =IF(Team!F6="","",Team!F6) | G6: =IF($A6="",0,IF(COUNTIFS(Urlaub!$A$5:$A$604,$A6,Urlaub!$B$5:$B$604,"<="&G$3,Urlaub!$C$5:$C$604,">="&G$3)>0,1,0)) -> 0 | H6: =IF($A6="",0,IF(COUNTIFS(Urlaub!$A$5:$A$604,$A6,Urlaub!$B$5:$B$604,"<="&H$3,Urlaub!$C$5:$C$604,">="&H$3)>0,1,0)) -> 0 | I6: =IF($A6="",0,IF(COUNTIFS(Urlaub!$A$5:$A$604,$A6,Urlaub!$B$5:$B$604,"<="&I$3,Urlaub!$C$5:$C$604,">="&I$3)>0,1,0)) -> 0 | J6: =IF($A6="",0,IF(COUNTIFS(Urlaub!$A$5:$A$604,$A6,Urlaub!$B$5:$B$604,"<="&J$3,Urlaub!$C$5:$C$604,">="&J$3)>0,1,0)) -> 0 | K6: =IF($A6="",0,IF(COUNTIFS(Urlaub!$A$5:$A$604,$A6,Urlaub!$B$5:$B$604,"<="&K$3,Urlaub!$C$5:$C$604,">="&K$3)>0,1,0)) -> 0 | L6: =IF($A6="",0,IF(COUNTIFS(Urlaub!$A$5:$A$604,$A6,Urlaub!$B$5:$B$604,"<="&L$3,Urlaub!$C$5:$C$604,">="&L$3)>0,1,0)) -> 0 | M6: =IF($A6="",0,IF(COUNTIFS(Urlaub!$A$5:$A$604,$A6,Urlaub!$B$5:$B$604,"<="&M$3,Urlaub!$C$5:$C$604,">="&M$3)>0,1,0)) -> 0 | N6: =IF($A6="",0,IF(COUNTIFS(Urlaub!$A$5:$A$604,$A6,Urlaub!$B$5:$B$604,"<="&N$3,Urlaub!$C$5:$C$604,">="&N$3)>0,1,0)) -> 0 | ... NH6: =IF($A6="",0,IF(COUNTIFS(Urlaub!$A$5:$A$604,$A6,Urlaub!$B$5:$B$604,"<="&NH$3,Urlaub!$C$5:$C$604,">="&NH$3)>0,1,0)) -> 0
A7: =IF(Team!A7="","",Team!A7) -> Beispiel Clara | B7: =IF(Team!B7="","",Team!B7) -> Ergotherapie | C7: =IF(Team!C7="","",Team!C7) -> Station 3 | D7: =IF(Team!D7="","",Team!D7) -> Tagesklinik | E7: =IF(Team!E7="","",Team!E7) | F7: =IF(Team!F7="","",Team!F7) | G7: =IF($A7="",0,IF(COUNTIFS(Urlaub!$A$5:$A$604,$A7,Urlaub!$B$5:$B$604,"<="&G$3,Urlaub!$C$5:$C$604,">="&G$3)>0,1,0)) -> 0 | H7: =IF($A7="",0,IF(COUNTIFS(Urlaub!$A$5:$A$604,$A7,Urlaub!$B$5:$B$604,"<="&H$3,Urlaub!$C$5:$C$604,">="&H$3)>0,1,0)) -> 0 | I7: =IF($A7="",0,IF(COUNTIFS(Urlaub!$A$5:$A$604,$A7,Urlaub!$B$5:$B$604,"<="&I$3,Urlaub!$C$5:$C$604,">="&I$3)>0,1,0)) -> 0 | J7: =IF($A7="",0,IF(COUNTIFS(Urlaub!$A$5:$A$604,$A7,Urlaub!$B$5:$B$604,"<="&J$3,Urlaub!$C$5:$C$604,">="&J$3)>0,1,0)) -> 0 | K7: =IF($A7="",0,IF(COUNTIFS(Urlaub!$A$5:$A$604,$A7,Urlaub!$B$5:$B$604,"<="&K$3,Urlaub!$C$5:$C$604,">="&K$3)>0,1,0)) -> 0 | L7: =IF($A7="",0,IF(COUNTIFS(Urlaub!$A$5:$A$604,$A7,Urlaub!$B$5:$B$604,"<="&L$3,Urlaub!$C$5:$C$604,">="&L$3)>0,1,0)) -> 0 | M7: =IF($A7="",0,IF(COUNTIFS(Urlaub!$A$5:$A$604,$A7,Urlaub!$B$5:$B$604,"<="&M$3,Urlaub!$C$5:$C$604,">="&M$3)>0,1,0)) -> 0 | N7: =IF($A7="",0,IF(COUNTIFS(Urlaub!$A$5:$A$604,$A7,Urlaub!$B$5:$B$604,"<="&N$3,Urlaub!$C$5:$C$604,">="&N$3)>0,1,0)) -> 0 | ... NH7: =IF($A7="",0,IF(COUNTIFS(Urlaub!$A$5:$A$604,$A7,Urlaub!$B$5:$B$604,"<="&NH$3,Urlaub!$C$5:$C$604,">="&NH$3)>0,1,0)) -> 0
A8: =IF(Team!A8="","",Team!A8) -> Beispiel David | B8: =IF(Team!B8="","",Team!B8) -> Musiktherapie | C8: =IF(Team!C8="","",Team!C8) -> Station 1A | D8: =IF(Team!D8="","",Team!D8) -> Station 2A | E8: =IF(Team!E8="","",Team!E8) | F8: =IF(Team!F8="","",Team!F8) | G8: =IF($A8="",0,IF(COUNTIFS(Urlaub!$A$5:$A$604,$A8,Urlaub!$B$5:$B$604,"<="&G$3,Urlaub!$C$5:$C$604,">="&G$3)>0,1,0)) -> 0 | H8: =IF($A8="",0,IF(COUNTIFS(Urlaub!$A$5:$A$604,$A8,Urlaub!$B$5:$B$604,"<="&H$3,Urlaub!$C$5:$C$604,">="&H$3)>0,1,0)) -> 0 | I8: =IF($A8="",0,IF(COUNTIFS(Urlaub!$A$5:$A$604,$A8,Urlaub!$B$5:$B$604,"<="&I$3,Urlaub!$C$5:$C$604,">="&I$3)>0,1,0)) -> 0 | J8: =IF($A8="",0,IF(COUNTIFS(Urlaub!$A$5:$A$604,$A8,Urlaub!$B$5:$B$604,"<="&J$3,Urlaub!$C$5:$C$604,">="&J$3)>0,1,0)) -> 0 | K8: =IF($A8="",0,IF(COUNTIFS(Urlaub!$A$5:$A$604,$A8,Urlaub!$B$5:$B$604,"<="&K$3,Urlaub!$C$5:$C$604,">="&K$3)>0,1,0)) -> 0 | L8: =IF($A8="",0,IF(COUNTIFS(Urlaub!$A$5:$A$604,$A8,Urlaub!$B$5:$B$604,"<="&L$3,Urlaub!$C$5:$C$604,">="&L$3)>0,1,0)) -> 0 | M8: =IF($A8="",0,IF(COUNTIFS(Urlaub!$A$5:$A$604,$A8,Urlaub!$B$5:$B$604,"<="&M$3,Urlaub!$C$5:$C$604,">="&M$3)>0,1,0)) -> 0 | N8: =IF($A8="",0,IF(COUNTIFS(Urlaub!$A$5:$A$604,$A8,Urlaub!$B$5:$B$604,"<="&N$3,Urlaub!$C$5:$C$604,">="&N$3)>0,1,0)) -> 0 | ... NH8: =IF($A8="",0,IF(COUNTIFS(Urlaub!$A$5:$A$604,$A8,Urlaub!$B$5:$B$604,"<="&NH$3,Urlaub!$C$5:$C$604,">="&NH$3)>0,1,0)) -> 0
A9: =IF(Team!A9="","",Team!A9) -> Beispiel Eva | B9: =IF(Team!B9="","",Team!B9) -> Musiktherapie | C9: =IF(Team!C9="","",Team!C9) -> Station 1B | D9: =IF(Team!D9="","",Team!D9) -> Station 3 | E9: =IF(Team!E9="","",Team!E9) | F9: =IF(Team!F9="","",Team!F9) | G9: =IF($A9="",0,IF(COUNTIFS(Urlaub!$A$5:$A$604,$A9,Urlaub!$B$5:$B$604,"<="&G$3,Urlaub!$C$5:$C$604,">="&G$3)>0,1,0)) -> 0 | H9: =IF($A9="",0,IF(COUNTIFS(Urlaub!$A$5:$A$604,$A9,Urlaub!$B$5:$B$604,"<="&H$3,Urlaub!$C$5:$C$604,">="&H$3)>0,1,0)) -> 0 | I9: =IF($A9="",0,IF(COUNTIFS(Urlaub!$A$5:$A$604,$A9,Urlaub!$B$5:$B$604,"<="&I$3,Urlaub!$C$5:$C$604,">="&I$3)>0,1,0)) -> 0 | J9: =IF($A9="",0,IF(COUNTIFS(Urlaub!$A$5:$A$604,$A9,Urlaub!$B$5:$B$604,"<="&J$3,Urlaub!$C$5:$C$604,">="&J$3)>0,1,0)) -> 0 | K9: =IF($A9="",0,IF(COUNTIFS(Urlaub!$A$5:$A$604,$A9,Urlaub!$B$5:$B$604,"<="&K$3,Urlaub!$C$5:$C$604,">="&K$3)>0,1,0)) -> 0 | L9: =IF($A9="",0,IF(COUNTIFS(Urlaub!$A$5:$A$604,$A9,Urlaub!$B$5:$B$604,"<="&L$3,Urlaub!$C$5:$C$604,">="&L$3)>0,1,0)) -> 0 | M9: =IF($A9="",0,IF(COUNTIFS(Urlaub!$A$5:$A$604,$A9,Urlaub!$B$5:$B$604,"<="&M$3,Urlaub!$C$5:$C$604,">="&M$3)>0,1,0)) -> 0 | N9: =IF($A9="",0,IF(COUNTIFS(Urlaub!$A$5:$A$604,$A9,Urlaub!$B$5:$B$604,"<="&N$3,Urlaub!$C$5:$C$604,">="&N$3)>0,1,0)) -> 0 | ... NH9: =IF($A9="",0,IF(COUNTIFS(Urlaub!$A$5:$A$604,$A9,Urlaub!$B$5:$B$604,"<="&NH$3,Urlaub!$C$5:$C$604,">="&NH$3)>0,1,0)) -> 0
A10: =IF(Team!A10="","",Team!A10) -> Beispiel Finn | B10: =IF(Team!B10="","",Team!B10) -> Bewegungstherapie | C10: =IF(Team!C10="","",Team!C10) -> Station 1A | D10: =IF(Team!D10="","",Team!D10) -> Tagesklinik | E10: =IF(Team!E10="","",Team!E10) | F10: =IF(Team!F10="","",Team!F10) | G10: =IF($A10="",0,IF(COUNTIFS(Urlaub!$A$5:$A$604,$A10,Urlaub!$B$5:$B$604,"<="&G$3,Urlaub!$C$5:$C$604,">="&G$3)>0,1,0)) -> 0 | H10: =IF($A10="",0,IF(COUNTIFS(Urlaub!$A$5:$A$604,$A10,Urlaub!$B$5:$B$604,"<="&H$3,Urlaub!$C$5:$C$604,">="&H$3)>0,1,0)) -> 0 | I10: =IF($A10="",0,IF(COUNTIFS(Urlaub!$A$5:$A$604,$A10,Urlaub!$B$5:$B$604,"<="&I$3,Urlaub!$C$5:$C$604,">="&I$3)>0,1,0)) -> 0 | J10: =IF($A10="",0,IF(COUNTIFS(Urlaub!$A$5:$A$604,$A10,Urlaub!$B$5:$B$604,"<="&J$3,Urlaub!$C$5:$C$604,">="&J$3)>0,1,0)) -> 0 | K10: =IF($A10="",0,IF(COUNTIFS(Urlaub!$A$5:$A$604,$A10,Urlaub!$B$5:$B$604,"<="&K$3,Urlaub!$C$5:$C$604,">="&K$3)>0,1,0)) -> 0 | L10: =IF($A10="",0,IF(COUNTIFS(Urlaub!$A$5:$A$604,$A10,Urlaub!$B$5:$B$604,"<="&L$3,Urlaub!$C$5:$C$604,">="&L$3)>0,1,0)) -> 0 | M10: =IF($A10="",0,IF(COUNTIFS(Urlaub!$A$5:$A$604,$A10,Urlaub!$B$5:$B$604,"<="&M$3,Urlaub!$C$5:$C$604,">="&M$3)>0,1,0)) -> 0 | N10: =IF($A10="",0,IF(COUNTIFS(Urlaub!$A$5:$A$604,$A10,Urlaub!$B$5:$B$604,"<="&N$3,Urlaub!$C$5:$C$604,">="&N$3)>0,1,0)) -> 0 | ... NH10: =IF($A10="",0,IF(COUNTIFS(Urlaub!$A$5:$A$604,$A10,Urlaub!$B$5:$B$604,"<="&NH$3,Urlaub!$C$5:$C$604,">="&NH$3)>0,1,0)) -> 0
A11: =IF(Team!A11="","",Team!A11) -> Beispiel Gül | B11: =IF(Team!B11="","",Team!B11) -> Bewegungstherapie | C11: =IF(Team!C11="","",Team!C11) -> Station 1B | D11: =IF(Team!D11="","",Team!D11) -> Station 2A | E11: =IF(Team!E11="","",Team!E11) -> Station 3 | F11: =IF(Team!F11="","",Team!F11) | G11: =IF($A11="",0,IF(COUNTIFS(Urlaub!$A$5:$A$604,$A11,Urlaub!$B$5:$B$604,"<="&G$3,Urlaub!$C$5:$C$604,">="&G$3)>0,1,0)) -> 0 | H11: =IF($A11="",0,IF(COUNTIFS(Urlaub!$A$5:$A$604,$A11,Urlaub!$B$5:$B$604,"<="&H$3,Urlaub!$C$5:$C$604,">="&H$3)>0,1,0)) -> 0 | I11: =IF($A11="",0,IF(COUNTIFS(Urlaub!$A$5:$A$604,$A11,Urlaub!$B$5:$B$604,"<="&I$3,Urlaub!$C$5:$C$604,">="&I$3)>0,1,0)) -> 0 | J11: =IF($A11="",0,IF(COUNTIFS(Urlaub!$A$5:$A$604,$A11,Urlaub!$B$5:$B$604,"<="&J$3,Urlaub!$C$5:$C$604,">="&J$3)>0,1,0)) -> 0 | K11: =IF($A11="",0,IF(COUNTIFS(Urlaub!$A$5:$A$604,$A11,Urlaub!$B$5:$B$604,"<="&K$3,Urlaub!$C$5:$C$604,">="&K$3)>0,1,0)) -> 0 | L11: =IF($A11="",0,IF(COUNTIFS(Urlaub!$A$5:$A$604,$A11,Urlaub!$B$5:$B$604,"<="&L$3,Urlaub!$C$5:$C$604,">="&L$3)>0,1,0)) -> 0 | M11: =IF($A11="",0,IF(COUNTIFS(Urlaub!$A$5:$A$604,$A11,Urlaub!$B$5:$B$604,"<="&M$3,Urlaub!$C$5:$C$604,">="&M$3)>0,1,0)) -> 0 | N11: =IF($A11="",0,IF(COUNTIFS(Urlaub!$A$5:$A$604,$A11,Urlaub!$B$5:$B$604,"<="&N$3,Urlaub!$C$5:$C$604,">="&N$3)>0,1,0)) -> 0 | ... NH11: =IF($A11="",0,IF(COUNTIFS(Urlaub!$A$5:$A$604,$A11,Urlaub!$B$5:$B$604,"<="&NH$3,Urlaub!$C$5:$C$604,">="&NH$3)>0,1,0)) -> 0
A12: =IF(Team!A12="","",Team!A12) | B12: =IF(Team!B12="","",Team!B12) | C12: =IF(Team!C12="","",Team!C12) | D12: =IF(Team!D12="","",Team!D12) | E12: =IF(Team!E12="","",Team!E12) | F12: =IF(Team!F12="","",Team!F12) | G12: =IF($A12="",0,IF(COUNTIFS(Urlaub!$A$5:$A$604,$A12,Urlaub!$B$5:$B$604,"<="&G$3,Urlaub!$C$5:$C$604,">="&G$3)>0,1,0)) -> 0 | H12: =IF($A12="",0,IF(COUNTIFS(Urlaub!$A$5:$A$604,$A12,Urlaub!$B$5:$B$604,"<="&H$3,Urlaub!$C$5:$C$604,">="&H$3)>0,1,0)) -> 0 | I12: =IF($A12="",0,IF(COUNTIFS(Urlaub!$A$5:$A$604,$A12,Urlaub!$B$5:$B$604,"<="&I$3,Urlaub!$C$5:$C$604,">="&I$3)>0,1,0)) -> 0 | J12: =IF($A12="",0,IF(COUNTIFS(Urlaub!$A$5:$A$604,$A12,Urlaub!$B$5:$B$604,"<="&J$3,Urlaub!$C$5:$C$604,">="&J$3)>0,1,0)) -> 0 | K12: =IF($A12="",0,IF(COUNTIFS(Urlaub!$A$5:$A$604,$A12,Urlaub!$B$5:$B$604,"<="&K$3,Urlaub!$C$5:$C$604,">="&K$3)>0,1,0)) -> 0 | L12: =IF($A12="",0,IF(COUNTIFS(Urlaub!$A$5:$A$604,$A12,Urlaub!$B$5:$B$604,"<="&L$3,Urlaub!$C$5:$C$604,">="&L$3)>0,1,0)) -> 0 | M12: =IF($A12="",0,IF(COUNTIFS(Urlaub!$A$5:$A$604,$A12,Urlaub!$B$5:$B$604,"<="&M$3,Urlaub!$C$5:$C$604,">="&M$3)>0,1,0)) -> 0 | N12: =IF($A12="",0,IF(COUNTIFS(Urlaub!$A$5:$A$604,$A12,Urlaub!$B$5:$B$604,"<="&N$3,Urlaub!$C$5:$C$604,">="&N$3)>0,1,0)) -> 0 | ... NH12: =IF($A12="",0,IF(COUNTIFS(Urlaub!$A$5:$A$604,$A12,Urlaub!$B$5:$B$604,"<="&NH$3,Urlaub!$C$5:$C$604,">="&NH$3)>0,1,0)) -> 0
A13: =IF(Team!A13="","",Team!A13) | B13: =IF(Team!B13="","",Team!B13) | C13: =IF(Team!C13="","",Team!C13) | D13: =IF(Team!D13="","",Team!D13) | E13: =IF(Team!E13="","",Team!E13) | F13: =IF(Team!F13="","",Team!F13) | G13: =IF($A13="",0,IF(COUNTIFS(Urlaub!$A$5:$A$604,$A13,Urlaub!$B$5:$B$604,"<="&G$3,Urlaub!$C$5:$C$604,">="&G$3)>0,1,0)) -> 0 | H13: =IF($A13="",0,IF(COUNTIFS(Urlaub!$A$5:$A$604,$A13,Urlaub!$B$5:$B$604,"<="&H$3,Urlaub!$C$5:$C$604,">="&H$3)>0,1,0)) -> 0 | I13: =IF($A13="",0,IF(COUNTIFS(Urlaub!$A$5:$A$604,$A13,Urlaub!$B$5:$B$604,"<="&I$3,Urlaub!$C$5:$C$604,">="&I$3)>0,1,0)) -> 0 | J13: =IF($A13="",0,IF(COUNTIFS(Urlaub!$A$5:$A$604,$A13,Urlaub!$B$5:$B$604,"<="&J$3,Urlaub!$C$5:$C$604,">="&J$3)>0,1,0)) -> 0 | K13: =IF($A13="",0,IF(COUNTIFS(Urlaub!$A$5:$A$604,$A13,Urlaub!$B$5:$B$604,"<="&K$3,Urlaub!$C$5:$C$604,">="&K$3)>0,1,0)) -> 0 | L13: =IF($A13="",0,IF(COUNTIFS(Urlaub!$A$5:$A$604,$A13,Urlaub!$B$5:$B$604,"<="&L$3,Urlaub!$C$5:$C$604,">="&L$3)>0,1,0)) -> 0 | M13: =IF($A13="",0,IF(COUNTIFS(Urlaub!$A$5:$A$604,$A13,Urlaub!$B$5:$B$604,"<="&M$3,Urlaub!$C$5:$C$604,">="&M$3)>0,1,0)) -> 0 | N13: =IF($A13="",0,IF(COUNTIFS(Urlaub!$A$5:$A$604,$A13,Urlaub!$B$5:$B$604,"<="&N$3,Urlaub!$C$5:$C$604,">="&N$3)>0,1,0)) -> 0 | ... NH13: =IF($A13="",0,IF(COUNTIFS(Urlaub!$A$5:$A$604,$A13,Urlaub!$B$5:$B$604,"<="&NH$3,Urlaub!$C$5:$C$604,">="&NH$3)>0,1,0)) -> 0
A14: =IF(Team!A14="","",Team!A14) | B14: =IF(Team!B14="","",Team!B14) | C14: =IF(Team!C14="","",Team!C14) | D14: =IF(Team!D14="","",Team!D14) | E14: =IF(Team!E14="","",Team!E14) | F14: =IF(Team!F14="","",Team!F14) | G14: =IF($A14="",0,IF(COUNTIFS(Urlaub!$A$5:$A$604,$A14,Urlaub!$B$5:$B$604,"<="&G$3,Urlaub!$C$5:$C$604,">="&G$3)>0,1,0)) -> 0 | H14: =IF($A14="",0,IF(COUNTIFS(Urlaub!$A$5:$A$604,$A14,Urlaub!$B$5:$B$604,"<="&H$3,Urlaub!$C$5:$C$604,">="&H$3)>0,1,0)) -> 0 | I14: =IF($A14="",0,IF(COUNTIFS(Urlaub!$A$5:$A$604,$A14,Urlaub!$B$5:$B$604,"<="&I$3,Urlaub!$C$5:$C$604,">="&I$3)>0,1,0)) -> 0 | J14: =IF($A14="",0,IF(COUNTIFS(Urlaub!$A$5:$A$604,$A14,Urlaub!$B$5:$B$604,"<="&J$3,Urlaub!$C$5:$C$604,">="&J$3)>0,1,0)) -> 0 | K14: =IF($A14="",0,IF(COUNTIFS(Urlaub!$A$5:$A$604,$A14,Urlaub!$B$5:$B$604,"<="&K$3,Urlaub!$C$5:$C$604,">="&K$3)>0,1,0)) -> 0 | L14: =IF($A14="",0,IF(COUNTIFS(Urlaub!$A$5:$A$604,$A14,Urlaub!$B$5:$B$604,"<="&L$3,Urlaub!$C$5:$C$604,">="&L$3)>0,1,0)) -> 0 | M14: =IF($A14="",0,IF(COUNTIFS(Urlaub!$A$5:$A$604,$A14,Urlaub!$B$5:$B$604,"<="&M$3,Urlaub!$C$5:$C$604,">="&M$3)>0,1,0)) -> 0 | N14: =IF($A14="",0,IF(COUNTIFS(Urlaub!$A$5:$A$604,$A14,Urlaub!$B$5:$B$604,"<="&N$3,Urlaub!$C$5:$C$604,">="&N$3)>0,1,0)) -> 0 | ... NH14: =IF($A14="",0,IF(COUNTIFS(Urlaub!$A$5:$A$604,$A14,Urlaub!$B$5:$B$604,"<="&NH$3,Urlaub!$C$5:$C$604,">="&NH$3)>0,1,0)) -> 0
A15: =IF(Team!A15="","",Team!A15) | B15: =IF(Team!B15="","",Team!B15) | C15: =IF(Team!C15="","",Team!C15) | D15: =IF(Team!D15="","",Team!D15) | E15: =IF(Team!E15="","",Team!E15) | F15: =IF(Team!F15="","",Team!F15) | G15: =IF($A15="",0,IF(COUNTIFS(Urlaub!$A$5:$A$604,$A15,Urlaub!$B$5:$B$604,"<="&G$3,Urlaub!$C$5:$C$604,">="&G$3)>0,1,0)) -> 0 | H15: =IF($A15="",0,IF(COUNTIFS(Urlaub!$A$5:$A$604,$A15,Urlaub!$B$5:$B$604,"<="&H$3,Urlaub!$C$5:$C$604,">="&H$3)>0,1,0)) -> 0 | I15: =IF($A15="",0,IF(COUNTIFS(Urlaub!$A$5:$A$604,$A15,Urlaub!$B$5:$B$604,"<="&I$3,Urlaub!$C$5:$C$604,">="&I$3)>0,1,0)) -> 0 | J15: =IF($A15="",0,IF(COUNTIFS(Urlaub!$A$5:$A$604,$A15,Urlaub!$B$5:$B$604,"<="&J$3,Urlaub!$C$5:$C$604,">="&J$3)>0,1,0)) -> 0 | K15: =IF($A15="",0,IF(COUNTIFS(Urlaub!$A$5:$A$604,$A15,Urlaub!$B$5:$B$604,"<="&K$3,Urlaub!$C$5:$C$604,">="&K$3)>0,1,0)) -> 0 | L15: =IF($A15="",0,IF(COUNTIFS(Urlaub!$A$5:$A$604,$A15,Urlaub!$B$5:$B$604,"<="&L$3,Urlaub!$C$5:$C$604,">="&L$3)>0,1,0)) -> 0 | M15: =IF($A15="",0,IF(COUNTIFS(Urlaub!$A$5:$A$604,$A15,Urlaub!$B$5:$B$604,"<="&M$3,Urlaub!$C$5:$C$604,">="&M$3)>0,1,0)) -> 0 | N15: =IF($A15="",0,IF(COUNTIFS(Urlaub!$A$5:$A$604,$A15,Urlaub!$B$5:$B$604,"<="&N$3,Urlaub!$C$5:$C$604,">="&N$3)>0,1,0)) -> 0 | ... NH15: =IF($A15="",0,IF(COUNTIFS(Urlaub!$A$5:$A$604,$A15,Urlaub!$B$5:$B$604,"<="&NH$3,Urlaub!$C$5:$C$604,">="&NH$3)>0,1,0)) -> 0
A16: =IF(Team!A16="","",Team!A16) | B16: =IF(Team!B16="","",Team!B16) | C16: =IF(Team!C16="","",Team!C16) | D16: =IF(Team!D16="","",Team!D16) | E16: =IF(Team!E16="","",Team!E16) | F16: =IF(Team!F16="","",Team!F16) | G16: =IF($A16="",0,IF(COUNTIFS(Urlaub!$A$5:$A$604,$A16,Urlaub!$B$5:$B$604,"<="&G$3,Urlaub!$C$5:$C$604,">="&G$3)>0,1,0)) -> 0 | H16: =IF($A16="",0,IF(COUNTIFS(Urlaub!$A$5:$A$604,$A16,Urlaub!$B$5:$B$604,"<="&H$3,Urlaub!$C$5:$C$604,">="&H$3)>0,1,0)) -> 0 | I16: =IF($A16="",0,IF(COUNTIFS(Urlaub!$A$5:$A$604,$A16,Urlaub!$B$5:$B$604,"<="&I$3,Urlaub!$C$5:$C$604,">="&I$3)>0,1,0)) -> 0 | J16: =IF($A16="",0,IF(COUNTIFS(Urlaub!$A$5:$A$604,$A16,Urlaub!$B$5:$B$604,"<="&J$3,Urlaub!$C$5:$C$604,">="&J$3)>0,1,0)) -> 0 | K16: =IF($A16="",0,IF(COUNTIFS(Urlaub!$A$5:$A$604,$A16,Urlaub!$B$5:$B$604,"<="&K$3,Urlaub!$C$5:$C$604,">="&K$3)>0,1,0)) -> 0 | L16: =IF($A16="",0,IF(COUNTIFS(Urlaub!$A$5:$A$604,$A16,Urlaub!$B$5:$B$604,"<="&L$3,Urlaub!$C$5:$C$604,">="&L$3)>0,1,0)) -> 0 | M16: =IF($A16="",0,IF(COUNTIFS(Urlaub!$A$5:$A$604,$A16,Urlaub!$B$5:$B$604,"<="&M$3,Urlaub!$C$5:$C$604,">="&M$3)>0,1,0)) -> 0 | N16: =IF($A16="",0,IF(COUNTIFS(Urlaub!$A$5:$A$604,$A16,Urlaub!$B$5:$B$604,"<="&N$3,Urlaub!$C$5:$C$604,">="&N$3)>0,1,0)) -> 0 | ... NH16: =IF($A16="",0,IF(COUNTIFS(Urlaub!$A$5:$A$604,$A16,Urlaub!$B$5:$B$604,"<="&NH$3,Urlaub!$C$5:$C$604,">="&NH$3)>0,1,0)) -> 0
